Workbook

Sheet Декомпозиция цикла
B1: Финмодель онлайн-школы в Узбекистане — один цикл
B2: Холодный запуск с таргета → дожим ИИ-продавцом и менеджером → тёплый запуск в Telegram-канале. Все суммы — в долларах США.
B3: Жёлтые ячейки с синими цифрами — вводные: меняй их
B4: Белые — формулы, не трогай. Три колонки — три сценария. Касса по месяцам — лист «Деньги по месяцам», откуда цифры — лист «Источники цифр», что было не так в старом файле — «Разбор исходника».
B5: Контекст — бриф рынка от 15.09.2026 (research/01-brif-rynka). Решение «идти / не идти» не принято: модель показывает, при каких цифрах цикл окупается. Ссылка на источник каждой цифры — в колонке H.
B6: Показатель | C6: Ед. | D6: Минимум | E6: Оптимум | F6: Максимум | G6: Как считается / откуда цифра | H6: Источник
B7: ИТОГ ЦИКЛА
B8: Выручка по договорам: холодный + тёплый запуск | C8: $ | D8: =D161 -> 1667.3642 | E8: =E161 -> 8093.8191 | F8: =F161 -> 34428.779 | G8: Сколько продали в деньгах — до комиссий и рассрочек
B9: Съели эквайринг, комиссия рассрочки, невыплаты, возвраты | C9: $ | D9: =-D166 -> -299.79208 | E9: =-E166 -> -840.11818 | F9: =-F166 -> -1977.9333 | G9: Расшифровка — в блоке 7
B10: Чистые деньги за цикл | C10: $ | D10: =D168 -> 1367.5721 | E10: =E168 -> 7253.7009 | F10: =F168 -> 32450.845 | G10: Выручка минус потери
B11: из них пришло сразу, в месяц продаж | C11: $ | D11: =D169 -> 1196.0003 | E11: =E169 -> 6643.8114 | F11: =F169 -> 30917.043 | G11: Полная оплата, партнёрская рассрочка, первый платёж своей рассрочки — минус возвраты
B12: из них придёт позже по своей рассрочке | C12: $ | D12: =D170 -> 171.57178 | E12: =E170 -> 609.8895 | F12: =F170 -> 1533.8021 | G12: Ежемесячные платежи учеников — по месяцам на листе «Деньги по месяцам»
B13: Расходы цикла | C13: $ | D13: =-D196 -> -9789.0799 | E13: =-E196 -> -10783.744 | F13: =-F196 -> -15037.099 | G13: Реклама, разовые вложения, ИИ, менеджер, команда, сервисы, кураторы, налог
B14: ПРИБЫЛЬ ЦИКЛА | C14: $ | D14: =D204 -> -8421.5078 | E14: =E204 -> -3530.0431 | F14: =F204 -> 17413.746 | G14: Чистые деньги минус расходы
B15: Прибыль без разовых вложений | C15: $ | D15: =D205 -> -7121.5078 | E15: =E205 -> -2230.0431 | F15: =F205 -> 18713.746 | G15: Сколько даст повторный цикл, когда ИИ-продавец уже настроен
B16: Прибыль школы после доли эксперта / партнёра | C16: $ | D16: =D207 -> -8421.5078 | E16: =E207 -> -3530.0431 | F16: =F207 -> 17413.746
B17: Собственнику после налога на дивиденды | C17: $ | D17: =D208 -> -8421.5078 | E17: =E208 -> -3530.0431 | F17: =F208 -> 15672.372 | G17: Если выводить прибыль из ООО нерезиденту
B18: ROMI: прибыль ÷ реклама | C18: x | D18: =D210 -> -1.6843016 | E18: =E210 -> -0.70600861 | F18: =F210 -> 3.4827492 | G18: Сколько прибыли на 1 $ рекламы
B19: Продаж за цикл | C19: шт | D19: =D187 -> 5.5578806 | E19: =E187 -> 26.979397 | F19: =F187 -> 114.7626 | G19: Холодный + тёплый запуск
B20: Цена холодной регистрации сейчас | C20: $ | D20: =D43 -> 7.8125 | E20: =E43 -> 4 | F20: =F43 -> 2 | G20: Из блока 1
B21: Предельная цена регистрации | C21: $ | D21: =D221 -> 1.747644 | E21: =E221 -> 4.8079656 | F21: =F221 -> 10.781498 | G21: Дороже этой цены реклама не отбивается, даже без учёта команды и окладов
B22: Рекламный бюджет, чтобы выйти в ноль | C22: $ | D22: =D225 -> не выходим | E22: =E225 -> 22476.206 | F22: =F225 -> 1033.9921 | G22: При текущих конверсиях. Приближённо — см. блок 9
B23: Нужно вложить до первых продаж | C23: $ | D23: =D201 -> 8380 | E23: =E201 -> 8380 | F23: =F201 -> 8380 | G23: Реклама + разовые вложения + команда + первый месяц окладов и сервисов
B24: Самая низкая точка кассы по месяцам | C24: $ | D24: ='Деньги по месяцам'!F28 -> -8482.9124 | E24: ='Деньги по месяцам'!K28 -> -3591.0214 | F24: ='Деньги по месяцам'!P28 -> 0 | G24: Минимум нарастающего итога на листе «Деньги по месяцам». Внутри месяца 1 разрыв больше — см. строку выше
B26: 0. ПРОДУКТ И ЦЕНЫ
B27: Цена курса в холодном запуске | C27: $ | D27: 300 | E27: 300 | F27: 300 | G27: Чек 300 $ — по ответу заказчика. У конкурентов: фриланс 170–595 $, ИИ-академии 255–510 $; база брифа — 212 $ | H27: бриф рынка
B28: Цена курса в тёплом запуске | C28: $ | D28: 300 | E28: 300 | F28: 300 | G28: Можно поставить спеццену для подписчиков канала | H28: оценка
B29: Апсейл: докупили старший тариф или сопровождение, % покупателей | C29: % | D29: 0 | E29: 0 | F29: 0 | G29: Рычаг «допродать». По умолчанию 0 — впиши, если будет старший тариф | H29: оценка
B30: Цена апсейла (доплата) | C30: $ | D30: 200 | E30: 200 | F30: 200 | H30: оценка
B31: Курс: сум за 1 $ (для справки) | C31: сум | D31: 11765 | E31: 11765 | F31: 11765 | G31: ЦБ РУз на 15.09.2026 — 11 765 сум | H31: cbu.uz
B32: Цена курса в сумах | C32: сум | D32: =D27*D31 -> 3529500 | E32: =E27*E31 -> 3529500 | F32: =F27*F31 -> 3529500 | G32: Для объявлений и лендинга
B34: 1. ХОЛОДНЫЙ ТРАФИК — таргет Instagram / Facebook
B35: Рекламный бюджет на холодный запуск | C35: $ | D35: 5000 | E35: 5000 | F35: 5000 | G35: Главный рычаг: поменяй — пересчитается весь цикл. Для Telegram-посевов подбери CPM, CTR и конверсию под свою цену регистрации | H35: оценка
B36: CPM — цена 1 000 показов | C36: $ | D36: 5 | E36: 4 | F36: 3 | G36: Meta в УЗ: 1–3 $ на широкую аудиторию, в Instagram 3–8 $ | H36: aksanov.digital
B37: Показы | C37: шт | D37: =IF(D36>0,D35/D36*1000,0) -> 1000000 | E37: =IF(E36>0,E35/E36*1000,0) -> 1250000 | F37: =IF(F36>0,F35/F36*1000,0) -> 1666666.7 | G37: Бюджет ÷ CPM × 1 000
B38: CTR — кликнули на рекламу | C38: % | D38: 0.008 | E38: 0.01 | F38: 0.012 | G38: Хорошим в Instagram УЗ считают 1,5–3% | H38: 101digital.uz
B39: Клики | C39: шт | D39: =D37*D38 -> 8000 | E39: =E37*E38 -> 12500 | F39: =F37*F38 -> 20000 | G39: Показы × CTR
B40: Цена клика (CPC) | C40: $ | D40: =IF(D39>0,D35/D39,0) -> 0.625 | E40: =IF(E39>0,E35/E39,0) -> 0.4 | F40: =IF(F39>0,F35/F39,0) -> 0.25 | G40: Бюджет ÷ клики
B41: Конверсия клик → регистрация (старт бота) | C41: % | D41: 0.08 | E41: 0.1 | F41: 0.125 | G41: Со страницы регистрации регистрируются 80–90%, с Telegram Ads на бота — 19–21% кликнувших; с Meta через лендинг и бота ниже | H41: vc.ru
B42: Регистрации | C42: чел | D42: =D39*D41 -> 640 | E42: =E39*E41 -> 1250 | F42: =F39*F41 -> 2500 | G42: Клики × конверсия
...

Sheet Деньги по месяцам
B1: Деньги по месяцам — когда приходят и уходят деньги
B2: Считается само из листа «Декомпозиция цикла», здесь ничего не вводится. Холодный запуск — месяц 1, тёплый — месяц «разрыв + 1». Своя рассрочка приходит частями в следующие месяцы.
C4: Минимум | H4: Оптимум | M4: Максимум
B5: Месяц | C5: Поступления | D5: Расходы | E5: Итог месяца | F5: Нарастающим итогом | H5: Поступления | I5: Расходы | J5: Итог месяца | K5: Нарастающим итогом | M5: Поступления | N5: Расходы | O5: Итог месяца | P5: Нарастающим итогом
B6: 1 | C6: =IF($B6=1,'Декомпозиция цикла'!$D$149-'Декомпозиция цикла'!$D$152,0)+IF(AND($B6>=2,$B6<='Декомпозиция цикла'!$D$143),'Декомпозиция цикла'!$D$151,0)+IF($B6='Декомпозиция цикла'!$D$186,'Декомпозиция цикла'!$D$155-'Декомпозиция цикла'!$D$158,0)+IF(AND($B6>='Декомпозиция цикла'!$D$186+1,$B6<='Декомпозиция цикла'!$D$186+'Декомпозиция цикла'!$D$143-1),'Декомпозиция цикла'!$D$157,0) -> 1125.1855 | D6: =IF($B6=1,'Декомпозиция цикла'!$D$198+'Декомпозиция цикла'!$D$189,0)+IF($B6='Декомпозиция цикла'!$D$186,'Декомпозиция цикла'!$D$199,0)+IF($B6<='Декомпозиция цикла'!$D$186,'Декомпозиция цикла'!$D$200,0)+'Декомпозиция цикла'!$D$183*C6 -> 7608.3034 | E6: =C6-D6 -> -6483.1179 | F6: =E6 -> -6483.1179 | H6: =IF($B6=1,'Декомпозиция цикла'!$E$149-'Декомпозиция цикла'!$E$152,0)+IF(AND($B6>=2,$B6<='Декомпозиция цикла'!$E$143),'Декомпозиция цикла'!$E$151,0)+IF($B6='Декомпозиция цикла'!$E$186,'Декомпозиция цикла'!$E$155-'Декомпозиция цикла'!$E$158,0)+IF(AND($B6>='Декомпозиция цикла'!$E$186+1,$B6<='Декомпозиция цикла'!$E$186+'Декомпозиция цикла'!$E$143-1),'Декомпозиция цикла'!$E$157,0) -> 5951.8679 | I6: =IF($B6=1,'Декомпозиция цикла'!$E$198+'Декомпозиция цикла'!$E$189,0)+IF($B6='Декомпозиция цикла'!$E$186,'Декомпозиция цикла'!$E$199,0)+IF($B6<='Декомпозиция цикла'!$E$186,'Декомпозиция цикла'!$E$200,0)+'Декомпозиция цикла'!$E$183*H6 -> 8475.0161 | J6: =H6-I6 -> -2523.1482 | K6: =J6 -> -2523.1482 | M6: =IF($B6=1,'Декомпозиция цикла'!$F$149-'Декомпозиция цикла'!$F$152,0)+IF(AND($B6>=2,$B6<='Декомпозиция цикла'!$F$143),'Декомпозиция цикла'!$F$151,0)+IF($B6='Декомпозиция цикла'!$F$186,'Декомпозиция цикла'!$F$155-'Декомпозиция цикла'!$F$158,0)+IF(AND($B6>='Декомпозиция цикла'!$F$186+1,$B6<='Декомпозиция цикла'!$F$186+'Декомпозиция цикла'!$F$143-1),'Декомпозиция цикла'!$F$157,0) -> 27088.17 | N6: =IF($B6=1,'Декомпозиция цикла'!$F$198+'Декомпозиция цикла'!$F$189,0)+IF($B6='Декомпозиция цикла'!$F$186,'Декомпозиция цикла'!$F$199,0)+IF($B6<='Декомпозиция цикла'!$F$186,'Декомпозиция цикла'!$F$200,0)+'Декомпозиция цикла'!$F$183*M6 -> 12162.227 | O6: =M6-N6 -> 14925.943 | P6: =O6 -> 14925.943
B7: 2 | C7: =IF($B7=1,'Декомпозиция цикла'!$D$149-'Декомпозиция цикла'!$D$152,0)+IF(AND($B7>=2,$B7<='Декомпозиция цикла'!$D$143),'Декомпозиция цикла'!$D$151,0)+IF($B7='Декомпозиция цикла'!$D$186,'Декомпозиция цикла'!$D$155-'Декомпозиция цикла'!$D$158,0)+IF(AND($B7>='Декомпозиция цикла'!$D$186+1,$B7<='Декомпозиция цикла'!$D$186+'Декомпозиция цикла'!$D$143-1),'Декомпозиция цикла'!$D$157,0) -> 53.804352 | D7: =IF($B7=1,'Декомпозиция цикла'!$D$198+'Декомпозиция цикла'!$D$189,0)+IF($B7='Декомпозиция цикла'!$D$186,'Декомпозиция цикла'!$D$199,0)+IF($B7<='Декомпозиция цикла'!$D$186,'Декомпозиция цикла'!$D$200,0)+'Декомпозиция цикла'!$D$183*C7 -> 1082.1522 | E7: =C7-D7 -> -1028.3478 | F7: =F6+E7 -> -7511.4658 | H7: =IF($B7=1,'Декомпозиция цикла'!$E$149-'Декомпозиция цикла'!$E$152,0)+IF(AND($B7>=2,$B7<='Декомпозиция цикла'!$E$143),'Декомпозиция цикла'!$E$151,0)+IF($B7='Декомпозиция цикла'!$E$186,'Декомпозиция цикла'!$E$155-'Декомпозиция цикла'!$E$158,0)+IF(AND($B7>='Декомпозиция цикла'!$E$186+1,$B7<='Декомпозиция цикла'!$E$186+'Декомпозиция цикла'!$E$143-1),'Декомпозиция цикла'!$E$157,0) -> 273.18519 | I7: =IF($B7=1,'Декомпозиция цикла'!$E$198+'Декомпозиция цикла'!$E$189,0)+IF($B7='Декомпозиция цикла'!$E$186,'Декомпозиция цикла'!$E$199,0)+IF($B7<='Декомпозиция цикла'!$E$186,'Декомпозиция цикла'!$E$200,0)+'Декомпозиция цикла'!$E$183*H7 -> 1090.9274 | J7: =H7-I7 -> -817.74222 | K7: =K6+J7 -> -3340.8904 | M7: =IF($B7=1,'Декомпозиция цикла'!$F$149-'Декомпозиция цикла'!$F$152,0)+IF(AND($B7>=2,$B7<='Декомпозиция цикла'!$F$143),'Декомпозиция цикла'!$F$151,0)+IF($B7='Декомпозиция цикла'!$F$186,'Декомпозиция цикла'!$F$155-'Декомпозиция цикла'!$F$158,0)+IF(AND($B7>='Декомпозиция цикла'!$F$186+1,$B7<='Декомпозиция цикла'!$F$186+'Декомпозиция цикла'!$F$143-1),'Декомпозиция цикла'!$F$157,0) -> 671.92538 | N7: =IF($B7=1,'Декомпозиция цикла'!$F$198+'Декомпозиция цикла'!$F$189,0)+IF($B7='Декомпозиция цикла'!$F$186,'Декомпозиция цикла'!$F$199,0)+IF($B7<='Декомпозиция цикла'!$F$186,'Декомпозиция цикла'!$F$200,0)+'Декомпозиция цикла'!$F$183*M7 -> 1106.877 | O7: =M7-N7 -> -434.95164 | P7: =P6+O7 -> 14490.992
B8: 3 | C8: =IF($B8=1,'Декомпозиция цикла'!$D$149-'Декомпозиция цикла'!$D$152,0)+IF(AND($B8>=2,$B8<='Декомпозиция цикла'!$D$143),'Декомпозиция цикла'!$D$151,0)+IF($B8='Декомпозиция цикла'!$D$186,'Декомпозиция цикла'!$D$155-'Декомпозиция цикла'!$D$158,0)+IF(AND($B8>='Декомпозиция цикла'!$D$186+1,$B8<='Декомпозиция цикла'!$D$186+'Декомпозиция цикла'!$D$143-1),'Декомпозиция цикла'!$D$157,0) -> 124.61921 | D8: =IF($B8=1,'Декомпозиция цикла'!$D$198+'Декомпозиция цикла'!$D$189,0)+IF($B8='Декомпозиция цикла'!$D$186,'Декомпозиция цикла'!$D$199,0)+IF($B8<='Декомпозиция цикла'!$D$186,'Декомпозиция цикла'!$D$200,0)+'Декомпозиция цикла'!$D$183*C8 -> 1096.0658 | E8: =C8-D8 -> -971.44661 | F8: =F7+E8 -> -8482.9124 | H8: =IF($B8=1,'Декомпозиция цикла'!$E$149-'Декомпозиция цикла'!$E$152,0)+IF(AND($B8>=2,$B8<='Декомпозиция цикла'!$E$143),'Декомпозиция цикла'!$E$151,0)+IF($B8='Декомпозиция цикла'!$E$186,'Декомпозиция цикла'!$E$155-'Декомпозиция цикла'!$E$158,0)+IF(AND($B8>='Декомпозиция цикла'!$E$186+1,$B8<='Декомпозиция цикла'!$E$186+'Декомпозиция цикла'!$E$143-1),'Декомпозиция цикла'!$E$157,0) -> 965.12865 | I8: =IF($B8=1,'Декомпозиция цикла'!$E$198+'Декомпозиция цикла'!$E$189,0)+IF($B8='Декомпозиция цикла'!$E$186,'Декомпозиция цикла'!$E$199,0)+IF($B8<='Декомпозиция цикла'!$E$186,'Декомпозиция цикла'!$E$200,0)+'Декомпозиция цикла'!$E$183*H8 -> 1215.2596 | J8: =H8-I8 -> -250.13099 | K8: =K7+J8 -> -3591.0214 | M8: =IF($B8=1,'Декомпозиция цикла'!$F$149-'Декомпозиция цикла'!$F$152,0)+IF(AND($B8>=2,$B8<='Декомпозиция цикла'!$F$143),'Декомпозиция цикла'!$F$151,0)+IF($B8='Декомпозиция цикла'!$F$186,'Декомпозиция цикла'!$F$155-'Декомпозиция цикла'!$F$158,0)+IF(AND($B8>='Декомпозиция цикла'!$F$186+1,$B8<='Декомпозиция цикла'!$F$186+'Декомпозиция цикла'!$F$143-1),'Декомпозиция цикла'!$F$157,0) -> 4500.7985 | N8: =IF($B8=1,'Декомпозиция цикла'!$F$198+'Декомпозиция цикла'!$F$189,0)+IF($B8='Декомпозиция цикла'!$F$186,'Декомпозиция цикла'!$F$199,0)+IF($B8<='Декомпозиция цикла'!$F$186,'Декомпозиция цикла'!$F$200,0)+'Декомпозиция цикла'!$F$183*M8 -> 1760.3971 | O8: =M8-N8 -> 2740.4014 | P8: =P7+O8 -> 17231.393
B9: 4 | C9: =IF($B9=1,'Декомпозиция цикла'!$D$149-'Декомпозиция цикла'!$D$152,0)+IF(AND($B9>=2,$B9<='Декомпозиция цикла'!$D$143),'Декомпозиция цикла'!$D$151,0)+IF($B9='Декомпозиция цикла'!$D$186,'Декомпозиция цикла'!$D$155-'Декомпозиция цикла'!$D$158,0)+IF(AND($B9>='Декомпозиция цикла'!$D$186+1,$B9<='Декомпозиция цикла'!$D$186+'Декомпозиция цикла'!$D$143-1),'Декомпозиция цикла'!$D$157,0) -> 57.190592 | D9: =IF($B9=1,'Декомпозиция цикла'!$D$198+'Декомпозиция цикла'!$D$189,0)+IF($B9='Декомпозиция цикла'!$D$186,'Декомпозиция цикла'!$D$199,0)+IF($B9<='Декомпозиция цикла'!$D$186,'Декомпозиция цикла'!$D$200,0)+'Декомпозиция цикла'!$D$183*C9 -> 2.2876237 | E9: =C9-D9 -> 54.902968 | F9: =F8+E9 -> -8428.0094 | H9: =IF($B9=1,'Декомпозиция цикла'!$E$149-'Декомпозиция цикла'!$E$152,0)+IF(AND($B9>=2,$B9<='Декомпозиция цикла'!$E$143),'Декомпозиция цикла'!$E$151,0)+IF($B9='Декомпозиция цикла'!$E$186,'Декомпозиция цикла'!$E$155-'Декомпозиция цикла'!$E$158,0)+IF(AND($B9>='Декомпозиция цикла'!$E$186+1,$B9<='Декомпозиция цикла'!$E$186+'Декомпозиция цикла'!$E$143-1),'Декомпозиция цикла'!$E$157,0) -> 31.75956 | I9: =IF($B9=1,'Декомпозиция цикла'!$E$198+'Декомпозиция цикла'!$E$189,0)+IF($B9='Декомпозиция цикла'!$E$186,'Декомпозиция цикла'!$E$199,0)+IF($B9<='Декомпозиция цикла'!$E$186,'Декомпозиция цикла'!$E$200,0)+'Декомпозиция цикла'!$E$183*H9 -> 1.2703824 | J9: =H9-I9 -> 30.489178 | K9: =K8+J9 -> -3560.5322 | M9: =IF($B9=1,'Декомпозиция цикла'!$F$149-'Декомпозиция цикла'!$F$152,0)+IF(AND($B9>=2,$B9<='Декомпозиция цикла'!$F$143),'Декомпозиция цикла'!$F$151,0)+IF($B9='Декомпозиция цикла'!$F$186,'Декомпозиция цикла'!$F$155-'Декомпозиция цикла'!$F$158,0)+IF(AND($B9>='Декомпозиция цикла'!$F$186+1,$B9<='Декомпозиция цикла'!$F$186+'Декомпозиция цикла'!$F$143-1),'Декомпозиция цикла'!$F$157,0) -> 94.975667 | N9: =IF($B9=1,'Декомпозиция цикла'!$F$198+'Декомпозиция цикла'!$F$189,0)+IF($B9='Декомпозиция цикла'!$F$186,'Декомпозиция цикла'!$F$199,0)+IF($B9<='Декомпозиция цикла'!$F$186,'Декомпозиция цикла'!$F$200,0)+'Декомпозиция цикла'!$F$183*M9 -> 3.7990267 | O9: =M9-N9 -> 91.17664 | P9: =P8+O9 -> 17322.57
B10: 5 | C10: =IF($B10=1,'Декомпозиция цикла'!$D$149-'Декомпозиция цикла'!$D$152,0)+IF(AND($B10>=2,$B10<='Декомпозиция цикла'!$D$143),'Декомпозиция цикла'!$D$151,0)+IF($B10='Декомпозиция цикла'!$D$186,'Декомпозиция цикла'!$D$155-'Декомпозиция цикла'!$D$158,0)+IF(AND($B10>='Декомпозиция цикла'!$D$186+1,$B10<='Декомпозиция цикла'!$D$186+'Декомпозиция цикла'!$D$143-1),'Декомпозиция цикла'!$D$157,0) -> 3.3862397 | D10: =IF($B10=1,'Декомпозиция цикла'!$D$198+'Декомпозиция цикла'!$D$189,0)+IF($B10='Декомпозиция цикла'!$D$186,'Декомпозиция цикла'!$D$199,0)+IF($B10<='Декомпозиция цикла'!$D$186,'Декомпозиция цикла'!$D$200,0)+'Декомпозиция цикла'!$D$183*C10 -> 0.13544959 | E10: =C10-D10 -> 3.2507901 | F10: =F9+E10 -> -8424.7586 | H10: =IF($B10=1,'Декомпозиция цикла'!$E$149-'Декомпозиция цикла'!$E$152,0)+IF(AND($B10>=2,$B10<='Декомпозиция цикла'!$E$143),'Декомпозиция цикла'!$E$151,0)+IF($B10='Декомпозиция цикла'!$E$186,'Декомпозиция цикла'!$E$155-'Декомпозиция цикла'!$E$158,0)+IF(AND($B10>='Декомпозиция цикла'!$E$186+1,$B10<='Декомпозиция цикла'!$E$186+'Декомпозиция цикла'!$E$143-1),'Декомпозиция цикла'!$E$157,0) -> 31.75956 | I10: =IF($B10=1,'Декомпозиция цикла'!$E$198+'Декомпозиция цикла'!$E$189,0)+IF($B10='Декомпозиция цикла'!$E$186,'Декомпозиция цикла'!$E$199,0)+IF($B10<='Декомпозиция цикла'!$E$186,'Декомпозиция цикла'!$E$200,0)+'Декомпозиция цикла'!$E$183*H10 -> 1.2703824 | J10: =H10-I10 -> 30.489178 | K10: =K9+J10 -> -3530.0431 | M10: =IF($B10=1,'Декомпозиция цикла'!$F$149-'Декомпозиция цикла'!$F$152,0)+IF(AND($B10>=2,$B10<='Декомпозиция цикла'!$F$143),'Декомпозиция цикла'!$F$151,0)+IF($B10='Декомпозиция цикла'!$F$186,'Декомпозиция цикла'!$F$155-'Декомпозиция цикла'!$F$158,0)+IF(AND($B10>='Декомпозиция цикла'!$F$186+1,$B10<='Декомпозиция цикла'!$F$186+'Декомпозиция цикла'!$F$143-1),'Декомпозиция цикла'!$F$157,0) -> 94.975667 | N10: =IF($B10=1,'Декомпозиция цикла'!$F$198+'Декомпозиция цикла'!$F$189,0)+IF($B10='Декомпозиция цикла'!$F$186,'Декомпозиция цикла'!$F$199,0)+IF($B10<='Декомпозиция цикла'!$F$186,'Декомпозиция цикла'!$F$200,0)+'Декомпозиция цикла'!$F$183*M10 -> 3.7990267 | O10: =M10-N10 -> 91.17664 | P10: =P9+O10 -> 17413.746
B11: 6 | C11: =IF($B11=1,'Декомпозиция цикла'!$D$149-'Декомпозиция цикла'!$D$152,0)+IF(AND($B11>=2,$B11<='Декомпозиция цикла'!$D$143),'Декомпозиция цикла'!$D$151,0)+IF($B11='Декомпозиция цикла'!$D$186,'Декомпозиция цикла'!$D$155-'Декомпозиция цикла'!$D$158,0)+IF(AND($B11>='Декомпозиция цикла'!$D$186+1,$B11<='Декомпозиция цикла'!$D$186+'Декомпозиция цикла'!$D$143-1),'Декомпозиция цикла'!$D$157,0) -> 3.3862397 | D11: =IF($B11=1,'Декомпозиция цикла'!$D$198+'Декомпозиция цикла'!$D$189,0)+IF($B11='Декомпозиция цикла'!$D$186,'Декомпозиция цикла'!$D$199,0)+IF($B11<='Декомпозиция цикла'!$D$186,'Декомпозиция цикла'!$D$200,0)+'Декомпозиция цикла'!$D$183*C11 -> 0.13544959 | E11: =C11-D11 -> 3.2507901 | F11: =F10+E11 -> -8421.5078 | H11: =IF($B11=1,'Декомпозиция цикла'!$E$149-'Декомпозиция цикла'!$E$152,0)+IF(AND($B11>=2,$B11<='Декомпозиция цикла'!$E$143),'Декомпозиция цикла'!$E$151,0)+IF($B11='Декомпозиция цикла'!$E$186,'Декомпозиция цикла'!$E$155-'Декомпозиция цикла'!$E$158,0)+IF(AND($B11>='Декомпозиция цикла'!$E$186+1,$B11<='Декомпозиция цикла'!$E$186+'Декомпозиция цикла'!$E$143-1),'Декомпозиция цикла'!$E$157,0) -> 0 | I11: =IF($B11=1,'Декомпозиция цикла'!$E$198+'Декомпозиция цикла'!$E$189,0)+IF($B11='Декомпозиция цикла'!$E$186,'Декомпозиция цикла'!$E$199,0)+IF($B11<='Декомпозиция цикла'!$E$186,'Декомпозиция цикла'!$E$200,0)+'Декомпозиция цикла'!$E$183*H11 -> 0 | J11: =H11-I11 -> 0 | K11: =K10+J11 -> -3530.0431 | M11: =IF($B11=1,'Декомпозиция цикла'!$F$149-'Декомпозиция цикла'!$F$152,0)+IF(AND($B11>=2,$B11<='Декомпозиция цикла'!$F$143),'Декомпозиция цикла'!$F$151,0)+IF($B11='Декомпозиция цикла'!$F$186,'Декомпозиция цикла'!$F$155-'Декомпозиция цикла'!$F$158,0)+IF(AND($B11>='Декомпозиция цикла'!$F$186+1,$B11<='Декомпозиция цикла'!$F$186+'Декомпозиция цикла'!$F$143-1),'Декомпозиция цикла'!$F$157,0) -> 0 | N11: =IF($B11=1,'Декомпозиция цикла'!$F$198+'Декомпозиция цикла'!$F$189,0)+IF($B11='Декомпозиция цикла'!$F$186,'Декомпозиция цикла'!$F$199,0)+IF($B11<='Декомпозиция цикла'!$F$186,'Декомпозиция цикла'!$F$200,0)+'Декомпозиция цикла'!$F$183*M11 -> 0 | O11: =M11-N11 -> 0 | P11: =P10+O11 -> 17413.746
B12: 7 | C12: =IF($B12=1,'Декомпозиция цикла'!$D$149-'Декомпозиция цикла'!$D$152,0)+IF(AND($B12>=2,$B12<='Декомпозиция цикла'!$D$143),'Декомпозиция цикла'!$D$151,0)+IF($B12='Декомпозиция цикла'!$D$186,'Декомпозиция цикла'!$D$155-'Декомпозиция цикла'!$D$158,0)+IF(AND($B12>='Декомпозиция цикла'!$D$186+1,$B12<='Декомпозиция цикла'!$D$186+'Декомпозиция цикла'!$D$143-1),'Декомпозиция цикла'!$D$157,0) -> 0 | D12: =IF($B12=1,'Декомпозиция цикла'!$D$198+'Декомпозиция цикла'!$D$189,0)+IF($B12='Декомпозиция цикла'!$D$186,'Декомпозиция цикла'!$D$199,0)+IF($B12<='Декомпозиция цикла'!$D$186,'Декомпозиция цикла'!$D$200,0)+'Декомпозиция цикла'!$D$183*C12 -> 0 | E12: =C12-D12 -> 0 | F12: =F11+E12 -> -8421.5078 | H12: =IF($B12=1,'Декомпозиция цикла'!$E$149-'Декомпозиция цикла'!$E$152,0)+IF(AND($B12>=2,$B12<='Декомпозиция цикла'!$E$143),'Декомпозиция цикла'!$E$151,0)+IF($B12='Декомпозиция цикла'!$E$186,'Декомпозиция цикла'!$E$155-'Декомпозиция цикла'!$E$158,0)+IF(AND($B12>='Декомпозиция цикла'!$E$186+1,$B12<='Декомпозиция цикла'!$E$186+'Декомпозиция цикла'!$E$143-1),'Декомпозиция цикла'!$E$157,0) -> 0 | I12: =IF($B12=1,'Декомпозиция цикла'!$E$198+'Декомпозиция цикла'!$E$189,0)+IF($B12='Декомпозиция цикла'!$E$186,'Декомпозиция цикла'!$E$199,0)+IF($B12<='Декомпозиция цикла'!$E$186,'Декомпозиция цикла'!$E$200,0)+'Декомпозиция цикла'!$E$183*H12 -> 0 | J12: =H12-I12 -> 0 | K12: =K11+J12 -> -3530.0431 | M12: =IF($B12=1,'Декомпозиция цикла'!$F$149-'Декомпозиция цикла'!$F$152,0)+IF(AND($B12>=2,$B12<='Декомпозиция цикла'!$F$143),'Декомпозиция цикла'!$F$151,0)+IF($B12='Декомпозиция цикла'!$F$186,'Декомпозиция цикла'!$F$155-'Декомпозиция цикла'!$F$158,0)+IF(AND($B12>='Декомпозиция цикла'!$F$186+1,$B12<='Декомпозиция цикла'!$F$186+'Декомпозиция цикла'!$F$143-1),'Декомпозиция цикла'!$F$157,0) -> 0 | N12: =IF($B12=1,'Декомпозиция цикла'!$F$198+'Декомпозиция цикла'!$F$189,0)+IF($B12='Декомпозиция цикла'!$F$186,'Декомпозиция цикла'!$F$199,0)+IF($B12<='Декомпозиция цикла'!$F$186,'Декомпозиция цикла'!$F$200,0)+'Декомпозиция цикла'!$F$183*M12 -> 0 | O12: =M12-N12 -> 0 | P12: =P11+O12 -> 17413.746
B13: 8 | C13: =IF($B13=1,'Декомпозиция цикла'!$D$149-'Декомпозиция цикла'!$D$152,0)+IF(AND($B13>=2,$B13<='Декомпозиция цикла'!$D$143),'Декомпозиция цикла'!$D$151,0)+IF($B13='Декомпозиция цикла'!$D$186,'Декомпозиция цикла'!$D$155-'Декомпозиция цикла'!$D$158,0)+IF(AND($B13>='Декомпозиция цикла'!$D$186+1,$B13<='Декомпозиция цикла'!$D$186+'Декомпозиция цикла'!$D$143-1),'Декомпозиция цикла'!$D$157,0) -> 0 | D13: =IF($B13=1,'Декомпозиция цикла'!$D$198+'Декомпозиция цикла'!$D$189,0)+IF($B13='Декомпозиция цикла'!$D$186,'Декомпозиция цикла'!$D$199,0)+IF($B13<='Декомпозиция цикла'!$D$186,'Декомпозиция цикла'!$D$200,0)+'Декомпозиция цикла'!$D$183*C13 -> 0 | E13: =C13-D13 -> 0 | F13: =F12+E13 -> -8421.5078 | H13: =IF($B13=1,'Декомпозиция цикла'!$E$149-'Декомпозиция цикла'!$E$152,0)+IF(AND($B13>=2,$B13<='Декомпозиция цикла'!$E$143),'Декомпозиция цикла'!$E$151,0)+IF($B13='Декомпозиция цикла'!$E$186,'Декомпозиция цикла'!$E$155-'Декомпозиция цикла'!$E$158,0)+IF(AND($B13>='Декомпозиция цикла'!$E$186+1,$B13<='Декомпозиция цикла'!$E$186+'Декомпозиция цикла'!$E$143-1),'Декомпозиция цикла'!$E$157,0) -> 0 | I13: =IF($B13=1,'Декомпозиция цикла'!$E$198+'Декомпозиция цикла'!$E$189,0)+IF($B13='Декомпозиция цикла'!$E$186,'Декомпозиция цикла'!$E$199,0)+IF($B13<='Декомпозиция цикла'!$E$186,'Декомпозиция цикла'!$E$200,0)+'Декомпозиция цикла'!$E$183*H13 -> 0 | J13: =H13-I13 -> 0 | K13: =K12+J13 -> -3530.0431 | M13: =IF($B13=1,'Декомпозиция цикла'!$F$149-'Декомпозиция цикла'!$F$152,0)+IF(AND($B13>=2,$B13<='Декомпозиция цикла'!$F$143),'Декомпозиция цикла'!$F$151,0)+IF($B13='Декомпозиция цикла'!$F$186,'Декомпозиция цикла'!$F$155-'Декомпозиция цикла'!$F$158,0)+IF(AND($B13>='Декомпозиция цикла'!$F$186+1,$B13<='Декомпозиция цикла'!$F$186+'Декомпозиция цикла'!$F$143-1),'Декомпозиция цикла'!$F$157,0) -> 0 | N13: =IF($B13=1,'Декомпозиция цикла'!$F$198+'Декомпозиция цикла'!$F$189,0)+IF($B13='Декомпозиция цикла'!$F$186,'Декомпозиция цикла'!$F$199,0)+IF($B13<='Декомпозиция цикла'!$F$186,'Декомпозиция цикла'!$F$200,0)+'Декомпозиция цикла'!$F$183*M13 -> 0 | O13: =M13-N13 -> 0 | P13: =P12+O13 -> 17413.746
B14: 9 | C14: =IF($B14=1,'Декомпозиция цикла'!$D$149-'Декомпозиция цикла'!$D$152,0)+IF(AND($B14>=2,$B14<='Декомпозиция цикла'!$D$143),'Декомпозиция цикла'!$D$151,0)+IF($B14='Декомпозиция цикла'!$D$186,'Декомпозиция цикла'!$D$155-'Декомпозиция цикла'!$D$158,0)+IF(AND($B14>='Декомпозиция цикла'!$D$186+1,$B14<='Декомпозиция цикла'!$D$186+'Декомпозиция цикла'!$D$143-1),'Декомпозиция цикла'!$D$157,0) -> 0 | D14: =IF($B14=1,'Декомпозиция цикла'!$D$198+'Декомпозиция цикла'!$D$189,0)+IF($B14='Декомпозиция цикла'!$D$186,'Декомпозиция цикла'!$D$199,0)+IF($B14<='Декомпозиция цикла'!$D$186,'Декомпозиция цикла'!$D$200,0)+'Декомпозиция цикла'!$D$183*C14 -> 0 | E14: =C14-D14 -> 0 | F14: =F13+E14 -> -8421.5078 | H14: =IF($B14=1,'Декомпозиция цикла'!$E$149-'Декомпозиция цикла'!$E$152,0)+IF(AND($B14>=2,$B14<='Декомпозиция цикла'!$E$143),'Декомпозиция цикла'!$E$151,0)+IF($B14='Декомпозиция цикла'!$E$186,'Декомпозиция цикла'!$E$155-'Декомпозиция цикла'!$E$158,0)+IF(AND($B14>='Декомпозиция цикла'!$E$186+1,$B14<='Декомпозиция цикла'!$E$186+'Декомпозиция цикла'!$E$143-1),'Декомпозиция цикла'!$E$157,0) -> 0 | I14: =IF($B14=1,'Декомпозиция цикла'!$E$198+'Декомпозиция цикла'!$E$189,0)+IF($B14='Декомпозиция цикла'!$E$186,'Декомпозиция цикла'!$E$199,0)+IF($B14<='Декомпозиция цикла'!$E$186,'Декомпозиция цикла'!$E$200,0)+'Декомпозиция цикла'!$E$183*H14 -> 0 | J14: =H14-I14 -> 0 | K14: =K13+J14 -> -3530.0431 | M14: =IF($B14=1,'Декомпозиция цикла'!$F$149-'Декомпозиция цикла'!$F$152,0)+IF(AND($B14>=2,$B14<='Декомпозиция цикла'!$F$143),'Декомпозиция цикла'!$F$151,0)+IF($B14='Декомпозиция цикла'!$F$186,'Декомпозиция цикла'!$F$155-'Декомпозиция цикла'!$F$158,0)+IF(AND($B14>='Декомпозиция цикла'!$F$186+1,$B14<='Декомпозиция цикла'!$F$186+'Декомпозиция цикла'!$F$143-1),'Декомпозиция цикла'!$F$157,0) -> 0 | N14: =IF($B14=1,'Декомпозиция цикла'!$F$198+'Декомпозиция цикла'!$F$189,0)+IF($B14='Декомпозиция цикла'!$F$186,'Декомпозиция цикла'!$F$199,0)+IF($B14<='Декомпозиция цикла'!$F$186,'Декомпозиция цикла'!$F$200,0)+'Декомпозиция цикла'!$F$183*M14 -> 0 | O14: =M14-N14 -> 0 | P14: =P13+O14 -> 17413.746
B15: 10 | C15: =IF($B15=1,'Декомпозиция цикла'!$D$149-'Декомпозиция цикла'!$D$152,0)+IF(AND($B15>=2,$B15<='Декомпозиция цикла'!$D$143),'Декомпозиция цикла'!$D$151,0)+IF($B15='Декомпозиция цикла'!$D$186,'Декомпозиция цикла'!$D$155-'Декомпозиция цикла'!$D$158,0)+IF(AND($B15>='Декомпозиция цикла'!$D$186+1,$B15<='Декомпозиция цикла'!$D$186+'Декомпозиция цикла'!$D$143-1),'Декомпозиция цикла'!$D$157,0) -> 0 | D15: =IF($B15=1,'Декомпозиция цикла'!$D$198+'Декомпозиция цикла'!$D$189,0)+IF($B15='Декомпозиция цикла'!$D$186,'Декомпозиция цикла'!$D$199,0)+IF($B15<='Декомпозиция цикла'!$D$186,'Декомпозиция цикла'!$D$200,0)+'Декомпозиция цикла'!$D$183*C15 -> 0 | E15: =C15-D15 -> 0 | F15: =F14+E15 -> -8421.5078 | H15: =IF($B15=1,'Декомпозиция цикла'!$E$149-'Декомпозиция цикла'!$E$152,0)+IF(AND($B15>=2,$B15<='Декомпозиция цикла'!$E$143),'Декомпозиция цикла'!$E$151,0)+IF($B15='Декомпозиция цикла'!$E$186,'Декомпозиция цикла'!$E$155-'Декомпозиция цикла'!$E$158,0)+IF(AND($B15>='Декомпозиция цикла'!$E$186+1,$B15<='Декомпозиция цикла'!$E$186+'Декомпозиция цикла'!$E$143-1),'Декомпозиция цикла'!$E$157,0) -> 0 | I15: =IF($B15=1,'Декомпозиция цикла'!$E$198+'Декомпозиция цикла'!$E$189,0)+IF($B15='Декомпозиция цикла'!$E$186,'Декомпозиция цикла'!$E$199,0)+IF($B15<='Декомпозиция цикла'!$E$186,'Декомпозиция цикла'!$E$200,0)+'Декомпозиция цикла'!$E$183*H15 -> 0 | J15: =H15-I15 -> 0 | K15: =K14+J15 -> -3530.0431 | M15: =IF($B15=1,'Декомпозиция цикла'!$F$149-'Декомпозиция цикла'!$F$152,0)+IF(AND($B15>=2,$B15<='Декомпозиция цикла'!$F$143),'Декомпозиция цикла'!$F$151,0)+IF($B15='Декомпозиция цикла'!$F$186,'Декомпозиция цикла'!$F$155-'Декомпозиция цикла'!$F$158,0)+IF(AND($B15>='Декомпозиция цикла'!$F$186+1,$B15<='Декомпозиция цикла'!$F$186+'Декомпозиция цикла'!$F$143-1),'Декомпозиция цикла'!$F$157,0) -> 0 | N15: =IF($B15=1,'Декомпозиция цикла'!$F$198+'Декомпозиция цикла'!$F$189,0)+IF($B15='Декомпозиция цикла'!$F$186,'Декомпозиция цикла'!$F$199,0)+IF($B15<='Декомпозиция цикла'!$F$186,'Декомпозиция цикла'!$F$200,0)+'Декомпозиция цикла'!$F$183*M15 -> 0 | O15: =M15-N15 -> 0 | P15: =P14+O15 -> 17413.746
B16: 11 | C16: =IF($B16=1,'Декомпозиция цикла'!$D$149-'Декомпозиция цикла'!$D$152,0)+IF(AND($B16>=2,$B16<='Декомпозиция цикла'!$D$143),'Декомпозиция цикла'!$D$151,0)+IF($B16='Декомпозиция цикла'!$D$186,'Декомпозиция цикла'!$D$155-'Декомпозиция цикла'!$D$158,0)+IF(AND($B16>='Декомпозиция цикла'!$D$186+1,$B16<='Декомпозиция цикла'!$D$186+'Декомпозиция цикла'!$D$143-1),'Декомпозиция цикла'!$D$157,0) -> 0 | D16: =IF($B16=1,'Декомпозиция цикла'!$D$198+'Декомпозиция цикла'!$D$189,0)+IF($B16='Декомпозиция цикла'!$D$186,'Декомпозиция цикла'!$D$199,0)+IF($B16<='Декомпозиция цикла'!$D$186,'Декомпозиция цикла'!$D$200,0)+'Декомпозиция цикла'!$D$183*C16 -> 0 | E16: =C16-D16 -> 0 | F16: =F15+E16 -> -8421.5078 | H16: =IF($B16=1,'Декомпозиция цикла'!$E$149-'Декомпозиция цикла'!$E$152,0)+IF(AND($B16>=2,$B16<='Декомпозиция цикла'!$E$143),'Декомпозиция цикла'!$E$151,0)+IF($B16='Декомпозиция цикла'!$E$186,'Декомпозиция цикла'!$E$155-'Декомпозиция цикла'!$E$158,0)+IF(AND($B16>='Декомпозиция цикла'!$E$186+1,$B16<='Декомпозиция цикла'!$E$186+'Декомпозиция цикла'!$E$143-1),'Декомпозиция цикла'!$E$157,0) -> 0 | I16: =IF($B16=1,'Декомпозиция цикла'!$E$198+'Декомпозиция цикла'!$E$189,0)+IF($B16='Декомпозиция цикла'!$E$186,'Декомпозиция цикла'!$E$199,0)+IF($B16<='Декомпозиция цикла'!$E$186,'Декомпозиция цикла'!$E$200,0)+'Декомпозиция цикла'!$E$183*H16 -> 0 | J16: =H16-I16 -> 0 | K16: =K15+J16 -> -3530.0431 | M16: =IF($B16=1,'Декомпозиция цикла'!$F$149-'Декомпозиция цикла'!$F$152,0)+IF(AND($B16>=2,$B16<='Декомпозиция цикла'!$F$143),'Декомпозиция цикла'!$F$151,0)+IF($B16='Декомпозиция цикла'!$F$186,'Декомпозиция цикла'!$F$155-'Декомпозиция цикла'!$F$158,0)+IF(AND($B16>='Декомпозиция цикла'!$F$186+1,$B16<='Декомпозиция цикла'!$F$186+'Декомпозиция цикла'!$F$143-1),'Декомпозиция цикла'!$F$157,0) -> 0 | N16: =IF($B16=1,'Декомпозиция цикла'!$F$198+'Декомпозиция цикла'!$F$189,0)+IF($B16='Декомпозиция цикла'!$F$186,'Декомпозиция цикла'!$F$199,0)+IF($B16<='Декомпозиция цикла'!$F$186,'Декомпозиция цикла'!$F$200,0)+'Декомпозиция цикла'!$F$183*M16 -> 0 | O16: =M16-N16 -> 0 | P16: =P15+O16 -> 17413.746
B17: 12 | C17: =IF($B17=1,'Декомпозиция цикла'!$D$149-'Декомпозиция цикла'!$D$152,0)+IF(AND($B17>=2,$B17<='Декомпозиция цикла'!$D$143),'Декомпозиция цикла'!$D$151,0)+IF($B17='Декомпозиция цикла'!$D$186,'Декомпозиция цикла'!$D$155-'Декомпозиция цикла'!$D$158,0)+IF(AND($B17>='Декомпозиция цикла'!$D$186+1,$B17<='Декомпозиция цикла'!$D$186+'Декомпозиция цикла'!$D$143-1),'Декомпозиция цикла'!$D$157,0) -> 0 | D17: =IF($B17=1,'Декомпозиция цикла'!$D$198+'Декомпозиция цикла'!$D$189,0)+IF($B17='Декомпозиция цикла'!$D$186,'Декомпозиция цикла'!$D$199,0)+IF($B17<='Декомпозиция цикла'!$D$186,'Декомпозиция цикла'!$D$200,0)+'Декомпозиция цикла'!$D$183*C17 -> 0 | E17: =C17-D17 -> 0 | F17: =F16+E17 -> -8421.5078 | H17: =IF($B17=1,'Декомпозиция цикла'!$E$149-'Декомпозиция цикла'!$E$152,0)+IF(AND($B17>=2,$B17<='Декомпозиция цикла'!$E$143),'Декомпозиция цикла'!$E$151,0)+IF($B17='Декомпозиция цикла'!$E$186,'Декомпозиция цикла'!$E$155-'Декомпозиция цикла'!$E$158,0)+IF(AND($B17>='Декомпозиция цикла'!$E$186+1,$B17<='Декомпозиция цикла'!$E$186+'Декомпозиция цикла'!$E$143-1),'Декомпозиция цикла'!$E$157,0) -> 0 | I17: =IF($B17=1,'Декомпозиция цикла'!$E$198+'Декомпозиция цикла'!$E$189,0)+IF($B17='Декомпозиция цикла'!$E$186,'Декомпозиция цикла'!$E$199,0)+IF($B17<='Декомпозиция цикла'!$E$186,'Декомпозиция цикла'!$E$200,0)+'Декомпозиция цикла'!$E$183*H17 -> 0 | J17: =H17-I17 -> 0 | K17: =K16+J17 -> -3530.0431 | M17: =IF($B17=1,'Декомпозиция цикла'!$F$149-'Декомпозиция цикла'!$F$152,0)+IF(AND($B17>=2,$B17<='Декомпозиция цикла'!$F$143),'Декомпозиция цикла'!$F$151,0)+IF($B17='Декомпозиция цикла'!$F$186,'Декомпозиция цикла'!$F$155-'Декомпозиция цикла'!$F$158,0)+IF(AND($B17>='Декомпозиция цикла'!$F$186+1,$B17<='Декомпозиция цикла'!$F$186+'Декомпозиция цикла'!$F$143-1),'Декомпозиция цикла'!$F$157,0) -> 0 | N17: =IF($B17=1,'Декомпозиция цикла'!$F$198+'Декомпозиция цикла'!$F$189,0)+IF($B17='Декомпозиция цикла'!$F$186,'Декомпозиция цикла'!$F$199,0)+IF($B17<='Декомпозиция цикла'!$F$186,'Декомпозиция цикла'!$F$200,0)+'Декомпозиция цикла'!$F$183*M17 -> 0 | O17: =M17-N17 -> 0 | P17: =P16+O17 -> 17413.746
B18: 13 | C18: =IF($B18=1,'Декомпозиция цикла'!$D$149-'Декомпозиция цикла'!$D$152,0)+IF(AND($B18>=2,$B18<='Декомпозиция цикла'!$D$143),'Декомпозиция цикла'!$D$151,0)+IF($B18='Декомпозиция цикла'!$D$186,'Декомпозиция цикла'!$D$155-'Декомпозиция цикла'!$D$158,0)+IF(AND($B18>='Декомпозиция цикла'!$D$186+1,$B18<='Декомпозиция цикла'!$D$186+'Декомпозиция цикла'!$D$143-1),'Декомпозиция цикла'!$D$157,0) -> 0 | D18: =IF($B18=1,'Декомпозиция цикла'!$D$198+'Декомпозиция цикла'!$D$189,0)+IF($B18='Декомпозиция цикла'!$D$186,'Декомпозиция цикла'!$D$199,0)+IF($B18<='Декомпозиция цикла'!$D$186,'Декомпозиция цикла'!$D$200,0)+'Декомпозиция цикла'!$D$183*C18 -> 0 | E18: =C18-D18 -> 0 | F18: =F17+E18 -> -8421.5078 | H18: =IF($B18=1,'Декомпозиция цикла'!$E$149-'Декомпозиция цикла'!$E$152,0)+IF(AND($B18>=2,$B18<='Декомпозиция цикла'!$E$143),'Декомпозиция цикла'!$E$151,0)+IF($B18='Декомпозиция цикла'!$E$186,'Декомпозиция цикла'!$E$155-'Декомпозиция цикла'!$E$158,0)+IF(AND($B18>='Декомпозиция цикла'!$E$186+1,$B18<='Декомпозиция цикла'!$E$186+'Декомпозиция цикла'!$E$143-1),'Декомпозиция цикла'!$E$157,0) -> 0 | I18: =IF($B18=1,'Декомпозиция цикла'!$E$198+'Декомпозиция цикла'!$E$189,0)+IF($B18='Декомпозиция цикла'!$E$186,'Декомпозиция цикла'!$E$199,0)+IF($B18<='Декомпозиция цикла'!$E$186,'Декомпозиция цикла'!$E$200,0)+'Декомпозиция цикла'!$E$183*H18 -> 0 | J18: =H18-I18 -> 0 | K18: =K17+J18 -> -3530.0431 | M18: =IF($B18=1,'Декомпозиция цикла'!$F$149-'Декомпозиция цикла'!$F$152,0)+IF(AND($B18>=2,$B18<='Декомпозиция цикла'!$F$143),'Декомпозиция цикла'!$F$151,0)+IF($B18='Декомпозиция цикла'!$F$186,'Декомпозиция цикла'!$F$155-'Декомпозиция цикла'!$F$158,0)+IF(AND($B18>='Декомпозиция цикла'!$F$186+1,$B18<='Декомпозиция цикла'!$F$186+'Декомпозиция цикла'!$F$143-1),'Декомпозиция цикла'!$F$157,0) -> 0 | N18: =IF($B18=1,'Декомпозиция цикла'!$F$198+'Декомпозиция цикла'!$F$189,0)+IF($B18='Декомпозиция цикла'!$F$186,'Декомпозиция цикла'!$F$199,0)+IF($B18<='Декомпозиция цикла'!$F$186,'Декомпозиция цикла'!$F$200,0)+'Декомпозиция цикла'!$F$183*M18 -> 0 | O18: =M18-N18 -> 0 | P18: =P17+O18 -> 17413.746
... B23: 18 | C23: =IF($B23=1,'Декомпозиция цикла'!$D$149-'Декомпозиция цикла'!$D$152,0)+IF(AND($B23>=2,$B23<='Декомпозиция цикла'!$D$143),'Декомпозиция цикла'!$D$151,0)+IF($B23='Декомпозиция цикла'!$D$186,'Декомпозиция цикла'!$D$155-'Декомпозиция цикла'!$D$158,0)+IF(AND($B23>='Декомпозиция цикла'!$D$186+1,$B23<='Декомпозиция цикла'!$D$186+'Декомпозиция цикла'!$D$143-1),'Декомпозиция цикла'!$D$157,0) -> 0 | D23: =IF($B23=1,'Декомпозиция цикла'!$D$198+'Декомпозиция цикла'!$D$189,0)+IF($B23='Декомпозиция цикла'!$D$186,'Декомпозиция цикла'!$D$199,0)+IF($B23<='Декомпозиция цикла'!$D$186,'Декомпозиция цикла'!$D$200,0)+'Декомпозиция цикла'!$D$183*C23 -> 0 | E23: =C23-D23 -> 0 | F23: =F22+E23 -> -8421.5078 | H23: =IF($B23=1,'Декомпозиция цикла'!$E$149-'Декомпозиция цикла'!$E$152,0)+IF(AND($B23>=2,$B23<='Декомпозиция цикла'!$E$143),'Декомпозиция цикла'!$E$151,0)+IF($B23='Декомпозиция цикла'!$E$186,'Декомпозиция цикла'!$E$155-'Декомпозиция цикла'!$E$158,0)+IF(AND($B23>='Декомпозиция цикла'!$E$186+1,$B23<='Декомпозиция цикла'!$E$186+'Декомпозиция цикла'!$E$143-1),'Декомпозиция цикла'!$E$157,0) -> 0 | I23: =IF($B23=1,'Декомпозиция цикла'!$E$198+'Декомпозиция цикла'!$E$189,0)+IF($B23='Декомпозиция цикла'!$E$186,'Декомпозиция цикла'!$E$199,0)+IF($B23<='Декомпозиция цикла'!$E$186,'Декомпозиция цикла'!$E$200,0)+'Декомпозиция цикла'!$E$183*H23 -> 0 | J23: =H23-I23 -> 0 | K23: =K22+J23 -> -3530.0431 | M23: =IF($B23=1,'Декомпозиция цикла'!$F$149-'Декомпозиция цикла'!$F$152,0)+IF(AND($B23>=2,$B23<='Декомпозиция цикла'!$F$143),'Декомпозиция цикла'!$F$151,0)+IF($B23='Декомпозиция цикла'!$F$186,'Декомпозиция цикла'!$F$155-'Декомпозиция цикла'!$F$158,0)+IF(AND($B23>='Декомпозиция цикла'!$F$186+1,$B23<='Декомпозиция цикла'!$F$186+'Декомпозиция цикла'!$F$143-1),'Декомпозиция цикла'!$F$157,0) -> 0 | N23: =IF($B23=1,'Декомпозиция цикла'!$F$198+'Декомпозиция цикла'!$F$189,0)+IF($B23='Декомпозиция цикла'!$F$186,'Декомпозиция цикла'!$F$199,0)+IF($B23<='Декомпозиция цикла'!$F$186,'Декомпозиция цикла'!$F$200,0)+'Декомпозиция цикла'!$F$183*M23 -> 0 | O23: =M23-N23 -> 0 | P23: =P22+O23 -> 17413.746
B24: Итого за 18 месяцев | C24: =SUM(C6:C23) -> 1367.5721 | D24: =SUM(D6:D23) -> 9789.0799 | E24: =SUM(E6:E23) -> -8421.5078 | H24: =SUM(H6:H23) -> 7253.7009 | I24: =SUM(I6:I23) -> 10783.744 | J24: =SUM(J6:J23) -> -3530.0431 | M24: =SUM(M6:M23) -> 32450.845 | N24: =SUM(N6:N23) -> 15037.099 | O24: =SUM(O6:O23) -> 17413.746
B26: Сверка поступлений с листом 1 (должно быть 0) | C26: =ROUND(C24-'Декомпозиция цикла'!$D$168,2) -> 0 | H26: =ROUND(H24-'Декомпозиция цикла'!$E$168,2) -> 0 | M26: =ROUND(M24-'Декомпозиция цикла'!$F$168,2) -> 0
B27: Сверка расходов с листом 1 (должно быть 0) | D27: =ROUND(D24-'Декомпозиция цикла'!$D$196,2) -> 0 | I27: =ROUND(I24-'Декомпозиция цикла'!$E$196,2) -> 0 | N27: =ROUND(N24-'Декомпозиция цикла'!$F$196,2) -> 0
B28: Самая низкая точка кассы (минимум нарастающего итога) | F28: =MIN(0,MIN(F6:F23)) -> -8482.9124 | K28: =MIN(0,MIN(K6:K23)) -> -3591.0214 | P28: =MIN(0,MIN(P6:P23)) -> 0
B29: Нужно вложить до первых продаж — внутри месяца 1 | F29: =-'Декомпозиция цикла'!$D$201 -> -8380 | K29: =-'Декомпозиция цикла'!$E$201 -> -8380 | P29: =-'Декомпозиция цикла'!$F$201 -> -8380

Sheet Разбор исходника
B1: Разбор исходного файла «декомпозиция Узбекситан .xlsx»
B2: Четыре листа — отдельные шаблоны из рублёвого запуска. Друг с другом они не связаны, трафик не связан с регистрациями, расходов и рассрочек нет, есть ошибка в формуле.
B4: Что считает каждый лист
C5: Лист | D5: Суть модели | F5: Главные цифры (как в файле)
C6: Модель продаж - анкета предзапи | D6: Прогрев → анкета предзаписи → закрытая презентация → автооплаты, брони, заказы → отдел продаж | F6: Охват 2 500 → 250 анкет → 150 на презентации → 25,6 продажи × 56 000 = 1,435 млн ₽. Сценарии: 1,9 / 5,4 / 10,7 млн ₽. Расходов нет.
C7: Модель продаж- через вебинармар | D7: Регистрации на бесплатный вебинар → участники → заказы, автооплаты, предоплаты → отдел продаж | F7: 600 регистраций → 300 участников → 40,5 продажи × 100 000 = 4,05 млн ₽ при трафике 500 тыс. («окупаемость» 8,1). Сценарии: 1,1 / 4,0 / 13,6 млн ₽.
C8: Модель продаж - гибридная | D8: Анкета → закрытый вебинар → трёхдневный марафон на всю базу → дожим письмами и зум-разборами | F8: Анкета 2,03 млн + марафон 5,36 млн + дожим 0,44 млн = 7,83 млн ₽ при трафике на марафон 2 млн.
C9: Трафик и лидмагнитная воронка | D9: Бюджеты по площадкам → подписчики → активации → предзаписи; вторая таблица — трипваер 2 900 ₽ → флагман 110 000 ₽ | F9: 13,5 млн ₽ → 2 683 предзаписи (≈5 031 ₽ за предзапись). Трипваер: 2,3 млн → 5,85 млн ₽ выручки (2,54x).
B11: Что не так и как исправлено в новой модели
B12: № | C12: Лист | D12: Ячейки | E12: Что там сейчас | F12: Почему это проблема | G12: Как в новой модели
B13: 1 | C13: Модель продаж - гибридная | D13: L12 | E13: Формула «(L11+L8*H27)*40%» даёт 440 001 ₽ | F13: Ошибка в формуле: число заявок с зум-разборов (3,5) прибавлено к деньгам, а не умножено на чек. Правильно (3,5 + 10) × 110 000 × 40% = 594 000 ₽ — недосчитано 154 тыс. | G13: Каждая строка «штуки × цена» считается отдельно; есть сверка «выручка − потери = чистые деньги».
B14: 2 | C14: Модель продаж- через вебинармар | D14: D61, I61, N61 | E14: Трафик 500 000 ₽ одинаковый при 300 / 500 / 1 000 регистраций | F14: Лишние регистрации достаются бесплатно: цена регистрации падает с 1 667 до 500 ₽, «окупаемость» растёт с 2,2x до 27,2x. Это эффект таблицы, а не рынка. | G14: Регистрации = бюджет ÷ CPM × 1 000 × CTR × конверсия. Больше регистраций — больше бюджет.
B15: 3 | C15: Модель продаж- через вебинармар | D15: D6, I8:I18 | E15: Источники регистраций на 3 900 человек, а в воронке 600 | F15: Таблица источников ни на что не влияет. | G15: Регистрации собираются в одну цепочку: трафик → канал → рассылка бота → посевы.
B16: 4 | C16: Модель продаж- через вебинармар | D16: D25, D58, I58, N58 | E16: «CV ОП — вебинарные» 2% от всех участников | F16: В базу попадают уже купившие и оставившие заявку — одни и те же люди считаются дважды. | G16: ИИ-продавец и менеджер дожимают только тех, кто ничего не сделал или не дошёл.
B17: 5 | C17: Модель продаж - анкета предзапи | D17: D24, D58, I58, N58 | E17: «CV ОП — анкета» от всех анкет | F17: Та же проблема: в базе уже купившие и оставившие бронь. | G17: Как в пункте 4.
B18: 6 | C18: через вебинармар, гибридная | D18: блок «Маркетинг и воронка» | E18: Не дошедшие до эфира (50% регистраций) нигде не дожимаются | F18: Потерян целый сегмент: не пришедших обычно дожимают записью и ботом (сколько это даёт в УЗ — не проверено). | G18: Отдельный сегмент «не дошли» → ИИ-продавец в боте → горячих передаёт менеджеру.
B19: 7 | C19: Модель продаж - гибридная | D19: L6, L9 | E19: Регистрации в дожиме = 1 000 вручную, «5%» внутри формулы | F19: Меняешь регистрации марафона (H6) — дожим не меняется. | G19: Все блоки связаны ссылками.
B20: 8 | C20: Модель продаж - гибридная | D20: H20 | E20: Одна конверсия ОП 45% и на брони, и на заявки | F20: На других листах бронь закрывается на 80% — здесь брони занижены. | G20: Отдельные ставки: бронь, заявка, горячий лид от ИИ.
B21: 9 | C21: Модель продаж - гибридная | D21: D28, H27, L16:L17 | E21: Чек 60 000 ₽ в анкете и 110 000 ₽ на марафоне; итог складывает оба; трафик на анкету не посчитан | F21: Итог 7,8 млн ₽ смешивает два продукта. Люди из анкеты, скорее всего, есть и на марафоне — возможен двойной счёт. | G21: Одна цепочка людей: холодный запуск → канал → тёплый запуск. Уже купившие из тёплого исключаются.
B22: 10 | C22: через вебинармар, гибридная | D22: D9, D42, I42, N42, H9 | E22: Пик = участники × 60%, число внутри формулы | F22: Поменять можно только правкой формулы. | G22: Внутри формул нет чисел — только ссылки на жёлтые ячейки.
B23: 11 | C23: Трафик и лидмагнитная воронка | D23: F6:G8, G15:H17, J15:K17 | E23: 20%, 10%, 7%, 3%, 15%, цены 2 900 и 110 000 ₽ внутри формул | F23: Воронку нельзя «покрутить» без правки формул. | G23: Каждая ставка — отдельная жёлтая ячейка.
B24: 12 | C24: Трафик и лидмагнитная воронка | D24: F8, F17 | E24: Активация ВК = 100% подписчиков, у остальных площадок 20% | F24: Завышает ВК. В воронках конкурентов в Узбекистане ВК нет — везде Telegram и Meta (бриф рынка, раздел «Воронки»). | G24: Трафик — таргет Instagram/Facebook, тёплая база — Telegram.
... B27: 15 | C27: Все листы | D27: форматы денег | E27: Рубли (р.), ВК, чеки 45–110 тыс. ₽ | F27: Цифры из российского запуска, не из Узбекистана. | G27: Доллары, курс сума для справки, каналы и бенчмарки Узбекистана.

Sheet Источники цифр
B1: Источники цифр — откуда стартовые значения
B2: Колонки «Минимум / Оптимум / Максимум» подтягиваются из модели. Бенчмарки собраны 15.09.2026; данных по конверсиям воронки в Узбекистане нет, поэтому часть взята по РФ — это отмечено в «Гео». Полное сырьё — research/04-finmodel-zapuska/бенчмарки-УЗ-2026-09.md.
B4: Показатель | C4: Ед. | D4: Минимум | E4: Оптимум | F4: Максимум | G4: Что известно / бенчмарк | H4: Гео | I4: Источник 1 | J4: Источник 2 | K4: Источник 3 | L4: Источник 4 | M4: Дата | N4: Уверенность
B5: Курс: сум за 1 $ (для справки) | C5: сум | D5: ='Декомпозиция цикла'!$D$31 -> 11765 | E5: ='Декомпозиция цикла'!$E$31 -> 11765 | F5: ='Декомпозиция цикла'!$F$31 -> 11765 | G5: ЦБ РУз: 11 765,21 сум за $ на 15.09.2026; в I полугодии 2026 — 11 935–12 320 | H5: UZ | I5: cbu.uz | J5: uz.kursiv.media | M5: 15.09.2026 | N5: высокая
B6: Цена курса в холодном запуске | C6: $ | D6: ='Декомпозиция цикла'!$D$27 -> 300 | E6: ='Декомпозиция цикла'!$E$27 -> 300 | F6: ='Декомпозиция цикла'!$F$27 -> 300 | G6: Цены конкурентов в УЗ: IT 21–255 $, SMM 42–212 $, фриланс 170–595 $, ИИ-академии 255–510 $; базовый чек брифа — 2,5 млн сум ≈ 212 $. Чек 300 $ — по ответу заказчика | H6: UZ | I6: бриф рынка | J6: moxieschool.uz | K6: sensorika.academy | L6: brains.uz | M6: 15.09.2026 | N6: средняя
B7: CPM — цена 1 000 показов | C7: $ | D7: ='Декомпозиция цикла'!$D$36 -> 5 | E7: ='Декомпозиция цикла'!$E$36 -> 4 | F7: ='Декомпозиция цикла'!$F$36 -> 3 | G7: Meta в УЗ: CPM 1–3 $ на широкую аудиторию; в Instagram 3–8 $; у другого агентства 0,5–2 $ | H7: UZ | I7: aksanov.digital | J7: 101digital.uz | K7: xyzlab.com | L7: unika-agency.com | M7: 2026 | N7: низкая-средняя
B8: CTR — кликнули на рекламу | C8: % | D8: ='Декомпозиция цикла'!$D$38 -> 0.008 | E8: ='Декомпозиция цикла'!$E$38 -> 0.01 | F8: ='Декомпозиция цикла'!$F$38 -> 0.012 | G8: Хороший CTR в Instagram УЗ — 1,5–3% (агентство); CTR Telegram Ads в кейсе курса — 0,98% (РФ) | H8: UZ / RU | I8: 101digital.uz | J8: vc.ru | M8: 2026 | N8: низкая-средняя
B9: Конверсия клик → регистрация (старт бота) | C9: % | D9: ='Декомпозиция цикла'!$D$41 -> 0.08 | E9: ='Декомпозиция цикла'!$E$41 -> 0.1 | F9: ='Декомпозиция цикла'!$F$41 -> 0.125 | G9: Со страницы регистрации регистрируются 80–90% (гайд); с Telegram Ads на бота подписываются 19–21% кликнувших (кейс курса). Для Meta → лендинг → бот берём ниже | H9: RU | I9: vc.ru | J9: vc.ru | M9: 2023–2026 | N9: средняя
B10: Цена регистрации (CPL) | C10: $ | D10: ='Декомпозиция цикла'!$D$43 -> 7.8125 | E10: ='Декомпозиция цикла'!$E$43 -> 4 | F10: ='Декомпозиция цикла'!$F$43 -> 2 | G10: Лид в образовании УЗ — 2,3–3,6 $; CPL Meta в УЗ — 1–15 $, в сезон июль–сентябрь 10–12 $ (практик); база брифа — 6 $; кейс вебинара СНГ — 2,61 $ | H10: UZ / СНГ | I10: aksanov.digital | J10: unika-agency.com | K10: t.me | L10: vc.ru | M10: 2021–2026 | N10: низкая-средняя
B11: Дошли на эфир (день 1), % регистраций | C11: % | D11: ='Декомпозиция цикла'!$D$47 -> 0.2 | E11: ='Декомпозиция цикла'!$E$47 -> 0.3 | F11: ='Декомпозиция цикла'!$F$47 -> 0.4 | G11: Регистрация → эфир: в среднем 15–20% (РФ, 2026); 20–30% — норма, 50% — хорошо (гайд СНГ, 2023); в брифе база 35% | H11: RU / СНГ | I11: sostav.ru | J11: vc.ru | K11: бриф рынка | M11: 2023–2026 | N11: средняя
B12: Автооплаты на эфире, % участников | C12: % | D12: ='Декомпозиция цикла'!$D$50 -> 0.01 | E12: ='Декомпозиция цикла'!$E$50 -> 0.015 | F12: ='Декомпозиция цикла'!$F$50 -> 0.02 | G12: Со вебинара покупают 5–20% зрителей (РФ). В брифе база: заявки — 12% участников, из них оплачивают 40%. Доли автооплат и броней отдельно не нашли — оценка | H12: RU | I12: skillspace.ru | J12: бриф рынка | M12: 2025–2026 | N12: низкая
B13: Менеджер: доводит бронь до оплаты, % | C13: % | D13: ='Декомпозиция цикла'!$D$67 -> 0.6 | E13: ='Декомпозиция цикла'!$E$67 -> 0.7 | F13: ='Декомпозиция цикла'!$F$67 -> 0.8 | G13: Заказ → оплата: 66,8% (вся платформа GetCourse, пик декабря 2025); 46% в примере финмодели школы; в исходном файле — 80% | H13: RU | I13: getcourse.ru | J13: noboring-finance.ru | M13: 2024–2026 | N13: высокая
B14: Менеджер: доводит заявку до оплаты, % | C14: % | D14: ='Декомпозиция цикла'!$D$68 -> 0.25 | E14: ='Декомпозиция цикла'!$E$68 -> 0.35 | F14: ='Декомпозиция цикла'!$F$68 -> 0.45 | G14: Звонок → оплата 50–55% по гайду (не проверено, пересказ в отчёте брифа); база брифа — 40%; в исходном файле — 40–50% | H14: RU | I14: бриф рынка | M14: 2026 | N14: низкая
B15: ИИ: оплатили сами по ссылке, % диалогов | C15: % | D15: ='Декомпозиция цикла'!$D$64 -> 0.01 | E15: ='Декомпозиция цикла'!$E$64 -> 0.015 | F15: ='Декомпозиция цикла'!$F$64 -> 0.02 | G15: ИИ-продавец: конверсия в чате выросла с ~10–12% до 25% за месяц (кейс самого вендора, B2B). Сколько даёт дожим в УЗ — не проверено, ставки ИИ — оценка | H15: RU | I15: sellergpt.ru | M15: 07.2025 | N15: низкая
B16: Отписки до тёплого запуска, % | C16: % | D16: ='Декомпозиция цикла'!$D$93 -> 0.15 | E16: ='Декомпозиция цикла'!$E$93 -> 0.1 | F16: ='Декомпозиция цикла'!$F$93 -> 0.08 | G16: Отписки 8–12% подписчиков (РФ, период не указан); по отпискам после запуска данных нет | H16: RU | I16: vc.ru | M16: 08.2024 | N16: низкая
B17: Зарегистрировались из канала, % целевой базы | C17: % | D17: ='Декомпозиция цикла'!$D$101 -> 0.1 | E17: ='Декомпозиция цикла'!$E$101 -> 0.15 | F17: ='Декомпозиция цикла'!$F$101 -> 0.2 | G17: Пост за 15 дней видят 36–44% подписчиков блогов, в маркетинге и tech — 7–10%. Серия анонсов охватывает больше одного поста; у каналов конкурентов в УЗ 300–4 000 подписчиков (бриф) | H17: RU / UZ | I17: telesputnik.ru | J17: бриф рынка | M17: 2025–2026 | N17: средняя
B18: Дошли в день 1, % регистраций | C18: % | D18: ='Декомпозиция цикла'!$D$110 -> 0.35 | E18: ='Декомпозиция цикла'!$E$110 -> 0.45 | F18: ='Декомпозиция цикла'!$F$110 -> 0.55 | G18: Холодный марафон: день 1 — 25%, день 2 — 14% регистраций. Тёплый: день 1 — 68%, на день 2 вернулись 72% пришедших | H18: RU | I18: vc.ru | J18: vc.ru | M18: 2022–2026 | N18: низкая-средняя
B19: Цена регистрации с посевов | C19: $ | D19: ='Декомпозиция цикла'!$D$107 -> 1.5 | E19: ='Декомпозиция цикла'!$E$107 -> 1 | F19: ='Декомпозиция цикла'!$F$107 -> 0.7 | G19: Telegram-посевы в УЗ: подписчик 7–12 тыс. сум (0,59–1,02 $), клик 0,08–0,17 $ (агентство, май 2026); подписчик Telegram Ads — 0,15–1,5 € | H19: UZ | I19: telegrad.uz | J19: aksanov.digital | M19: 2026 | N19: средняя
B20: Партнёрская рассрочка (Uzum Nasiya, Alif), % продаж | C20: % | D20: ='Декомпозиция цикла'!$D$137 -> 0.35 | E20: ='Декомпозиция цикла'!$E$137 -> 0.3 | F20: ='Декомпозиция цикла'!$F$137 -> 0.25 | G20: Рассрочка 0% на 6–12 мес через Uzum и Alif Nasiya — стандарт рынка УЗ (бриф). Alif одобряет 50–60% заявок, Uzum Nasiya — до 97%. С 01.01.2027 ПП-294: максимум 12 мес | H20: UZ | I20: бриф рынка | J20: spot.uz | K20: uzum.uz | L20: yuz.uz | M20: 2025–2026 | N20: средняя
B21: Комиссия партнёрской рассрочки для школы, % | C21: % | D21: ='Декомпозиция цикла'!$D$141 -> 0.15 | E21: ='Декомпозиция цикла'!$E$141 -> 0.1 | F21: ='Декомпозиция цикла'!$F$141 -> 0.06 | G21: Комиссию школы у Uzum и Alif найти не удалось (бриф). Если 0% для покупателя, наценку платит школа; покупателю наценка на 12 мес — 27–44%. Ориентир РФ (Prodamus): 8,5% / 10% / 15% за 3 / 6 / 12 мес | H21: UZ / RU | I21: бриф рынка | J21: gazeta.uz | K21: prodamus.ru | M21: 2025–2026 | N21: низкая
B22: Своя рассрочка: не доплатят, % от остатка | C22: % | D22: ='Декомпозиция цикла'!$D$146 -> 0.25 | E22: ='Декомпозиция цикла'!$E$146 -> 0.15 | F22: ='Декомпозиция цикла'!$F$146 -> 0.1 | G22: Данных по невыплатам нет. Оценка ресёрча: первый платёж 30%, не доплачивают 15% остатка; школа выходит в ноль после 3–4 из 12 платежей (РФ) | H22: RU | I22: blog.whiteedtech.ru | M22: 03.2024 | N22: низкая
B23: Эквайринг (Payme, Click, Uzum), % с платежа | C23: % | D23: ='Декомпозиция цикла'!$D$140 -> 0.02 | E23: ='Декомпозиция цикла'!$E$140 -> 0.015 | F23: ='Декомпозиция цикла'!$F$140 -> 0.01 | G23: Payme / Click / Uzum: комиссия 0,8–2%, подключение ~2 недели, только местным юрлицам; UzQR — 0,65% | H23: UZ | I23: uzneo.uz | J23: vc.ru | K23: gazeta.uz | M23: 2026 | N23: средняя-высокая
B24: Возвраты, % выручки | C24: % | D24: ='Декомпозиция цикла'!$D$147 -> 0.08 | E24: ='Декомпозиция цикла'!$E$147 -> 0.05 | F24: ='Декомпозиция цикла'!$F$147 -> 0.03 | G24: Возвраты 5% — допущение брифа; данных по Узбекистану нет | H24: — | I24: бриф рынка | M24: 15.09.2026 | N24: низкая
B25: ИИ-продавец: разработка и настройка, разово | C25: $ | D25: ='Декомпозиция цикла'!$D$174 -> 1300 | E25: ='Декомпозиция цикла'!$E$174 -> 1300 | F25: ='Декомпозиция цикла'!$F$174 -> 1300 | G25: Разработка ИИ-бота в УЗ — 5–25 млн сум (пакеты 10 / 20 / 35 млн); ИИ и хостинг — 0,3–3 млн сум в месяц | H25: UZ | I25: innosoft.uz | M25: 07.2026 | N25: средняя
B26: ИИ-продавец: доплата за 1 диалог | C26: $ | D26: ='Декомпозиция цикла'!$D$177 -> 0.05 | E26: ='Декомпозиция цикла'!$E$177 -> 0.05 | F26: ='Декомпозиция цикла'!$F$177 -> 0.05 | G26: Сервисы берут 5–30 ₽ за диалог (только сниппет поиска, не проверено); на своём боте токены дешевле | H26: RU | I26: botseller.ai | M26: 2025–2026 | N26: низкая
B27: Менеджер: % с выручки своих сделок | C27: % | D27: ='Декомпозиция цикла'!$D$179 -> 0.1 | E27: ='Декомпозиция цикла'!$E$179 -> 0.1 | F27: ='Декомпозиция цикла'!$F$179 -> 0.1 | G27: Затраты на продажи 10% выручки — допущение брифа | H27: — | I27: бриф рынка | M27: 15.09.2026 | N27: низкая
B28: Менеджер: оклад, $ в месяц | C28: $ | D28: ='Декомпозиция цикла'!$D$178 -> 300 | E28: ='Декомпозиция цикла'!$E$178 -> 300 | F28: ='Декомпозиция цикла'!$F$178 -> 300 | G28: Оклад, команда и сервисы — оценка, уточнить у своей команды | H28: — | I28: — | M28: — | N28: низкая
B29: Обучение: кураторы и поддержка на 1 ученика | C29: $ | D29: ='Декомпозиция цикла'!$D$182 -> 15 | E29: ='Декомпозиция цикла'!$E$182 -> 15 | F29: ='Декомпозиция цикла'!$F$182 -> 15 | G29: Кураторы на ученика: 10 / 15 / 25 $ при чеке 85 / 212 / 425 $ — допущение брифа | H29: — | I29: бриф рынка | M29: 15.09.2026 | N29: низкая
B30: Налог, % от поступлений | C30: % | D30: ='Декомпозиция цикла'!$D$183 -> 0.04 | E30: ='Декомпозиция цикла'!$E$183 -> 0.04 | F30: ='Декомпозиция цикла'!$F$183 -> 0.04 | G30: ООО: налог с оборота 4% до 1 млрд сум в год (≈ 85 тыс. $); выше — НДС 12% и налог на прибыль 15%; ИП и самозанятые — 1% | H30: UZ | I30: buxgalter.uz | J30: spot.uz | K30: buxgalter.uz | M30: 2026 | N30: высокая
B31: Налог на дивиденды при выводе прибыли, % | C31: % | D31: ='Декомпозиция цикла'!$D$185 -> 0.1 | E31: ='Декомпозиция цикла'!$E$185 -> 0.1 | F31: ='Декомпозиция цикла'!$F$185 -> 0.1 | G31: Дивиденды нерезиденту — 10%, для России по договору тоже 10%. На общем режиме до кармана доходит ≈ 76,5 $ со 100 $ прибыли (бриф) | H31: UZ | I31: taxsummaries.pwc.com | J31: бриф рынка | M31: 16.01.2026 | N31: высокая
B32: Прочие разовые вложения: ООО, юрист, запись курса, лендинг, бот | C32: $ | D32: ='Декомпозиция цикла'!$D$175 -> 0 | E32: ='Декомпозиция цикла'!$E$175 -> 0 | F32: ='Декомпозиция цикла'!$F$175 -> 0 | G32: Госпошлина за регистрацию ООО — 300 тыс. сум ≈ 25 $; принимать оплату массовой аудитории можно только через своё ООО (бриф) | H32: UZ | I32: azma.uz | J32: бриф рынка | M32: 2026 | N32: средняя
