Workbook

Sheet Цены тарифов
A1: Цены тарифов «Первый заказ на ИИ»: рубли, сумы, доллары
A2: Синий шрифт — вводишь сам. Чёрный — считает формула. Жёлтая заливка — главные допущения. Поменяй курс или наценку, и все цены пересчитаются.
A4: Исходные данные
A5: Дата курса ЦБ Узбекистана | B5: 46294 | C5: cbu.uz/ru/arkhiv-kursov-valyut/json/
A6: 1 доллар = сум | B6: 11806.97
A7: 1 рубль = сум | B7: 139.86
A8: 1 доллар = рублей (считается) | B8: =B6/B7 -> 84.41992
A9: Наценка «Зрителям эфира» к спеццене | B9: 0.25 | C9: Итог созвона 28.09: +25%. Другие варианты — лист «Варианты цен»
A10: Наценка «Обычная» к спеццене | B10: 0.75 | C10: Итог созвона 28.09: +75%
A12: Округление сумов, как в презентации
A13: Тариф | B13: Шаг округления, сум | C13: Хвост, сум | D13: Как выглядит цена
A14: Базовый | B14: 10000 | C14: 1000 | D14: …9 000
A15: Про | B15: 10000 | C15: 1000 | D15: …9 000
A16: Наставничество | B16: 100000 | C16: 10000 | D16: …90 000
A18: 1. Цены в рублях — итог созвона 28.09.2026
A19: Тариф | B19: Спеццена (24 часа после эфира), ₽ | C19: Зрителям эфира, ₽ | D19: Обычная, ₽
A20: Базовый | B20: 4900 | C20: =B20*(1+$B$9) -> 6125 | D20: =B20*(1+$B$10) -> 8575
A21: Про | B21: 12000 | C21: =B21*(1+$B$9) -> 15000 | D21: =B21*(1+$B$10) -> 21000
A22: Наставничество | B22: 100000 | C22: =B22*(1+$B$9) -> 125000 | D22: =B22*(1+$B$10) -> 175000
A24: 2. Цены в сумах — точный пересчёт (рубли × курс)
A25: Тариф | B25: Спеццена (24 часа после эфира), сум | C25: Зрителям эфира, сум | D25: Обычная, сум
A26: Базовый | B26: =B20*$B$7 -> 685314 | C26: =C20*$B$7 -> 856642.5 | D26: =D20*$B$7 -> 1199299.5
A27: Про | B27: =B21*$B$7 -> 1678320 | C27: =C21*$B$7 -> 2097900 | D27: =D21*$B$7 -> 2937060
A28: Наставничество | B28: =B22*$B$7 -> 13986000 | C28: =C22*$B$7 -> 17482500 | D28: =D22*$B$7 -> 24475500
A30: 3. Цены в сумах — как в презентации (округлено)
A31: Тариф | B31: Спеццена (24 часа после эфира), сум | C31: Зрителям эфира, сум | D31: Обычная, сум
A32: Базовый | B32: =ROUND((B26+$C14)/$B14,0)*$B14-$C14 -> 689000 | C32: =ROUND((C26+$C14)/$B14,0)*$B14-$C14 -> 859000 | D32: =ROUND((D26+$C14)/$B14,0)*$B14-$C14 -> 1199000
A33: Про | B33: =ROUND((B27+$C15)/$B15,0)*$B15-$C15 -> 1679000 | C33: =ROUND((C27+$C15)/$B15,0)*$B15-$C15 -> 2099000 | D33: =ROUND((D27+$C15)/$B15,0)*$B15-$C15 -> 2939000
A34: Наставничество | B34: =ROUND((B28+$C16)/$B16,0)*$B16-$C16 -> 13990000 | C34: =ROUND((C28+$C16)/$B16,0)*$B16-$C16 -> 17490000 | D34: =ROUND((D28+$C16)/$B16,0)*$B16-$C16 -> 24490000
A36: 4. Цены в долларах — пересчёт цен из презентации (сумы ÷ курс, до целого доллара)
A37: Тариф | B37: Спеццена (24 часа после эфира), $ | C37: Зрителям эфира, $ | D37: Обычная, $
A38: Базовый | B38: =ROUND(B32/$B$6,0) -> 58 | C38: =ROUND(C32/$B$6,0) -> 73 | D38: =ROUND(D32/$B$6,0) -> 102
A39: Про | B39: =ROUND(B33/$B$6,0) -> 142 | C39: =ROUND(C33/$B$6,0) -> 178 | D39: =ROUND(D33/$B$6,0) -> 249
A40: Наставничество | B40: =ROUND(B34/$B$6,0) -> 1185 | C40: =ROUND(C34/$B$6,0) -> 1481 | D40: =ROUND(D34/$B$6,0) -> 2074
A42: 5. Цены в долларах — круглые, если продавать именно в долларах (предложение Claude)
A43: Тариф | B43: Спеццена (24 часа после эфира), $ | C43: Зрителям эфира, $ | D43: Обычная, $ | E43: «Зрителям» к спеццене | F43: «Обычная» к спеццене | G43: Спеццена к пересчёту
A44: Базовый | B44: 59 | C44: 75 | D44: 105 | E44: =C44/B44-1 -> 0.27118644 | F44: =D44/B44-1 -> 0.77966102 | G44: =B44/(B32/$B$6)-1 -> 0.011046778
A45: Про | B45: 139 | C45: 175 | D45: 245 | E45: =C45/B45-1 -> 0.25899281 | F45: =D45/B45-1 -> 0.76258993 | G45: =B45/(B33/$B$6)-1 -> -0.022531965
A46: Наставничество | B46: 1190 | C46: 1490 | D46: 2090 | E46: =C46/B46-1 -> 0.25210084 | F46: =D46/B46-1 -> 0.75630252 | G46: =B46/(B34/$B$6)-1 -> 0.0043098142
A47: Если оплата идёт в сумах, доллар — только ориентир со знаком ≈: курс изменится.
...

Sheet Услуги
A1: Сколько платят за услуги: рубли (созвон) → сумы → доллары
A2: Курс берётся с листа «Цены тарифов» (зелёный). Рубли из созвона — синие, их можно менять.
A3: 1 рубль = сум | B3: ='Цены тарифов'!B7 -> 139.86 | C3: 1 доллар = сум | D3: ='Цены тарифов'!B6 -> 11806.97
A4: Услуга | B4: За что платят | C4: От, ₽ | D4: До, ₽ | E4: От, сум | F4: До, сум | G4: От, $ | H4: До, $ | I4: Как написано в презентации (на 29.09.2026)
A5: Чат-бот для бизнеса | B5: за проект | C5: 5000 | D5: 50000 | E5: =IF(C5="","",C5*$B$3) -> 699300 | F5: =IF(D5="","",D5*$B$3) -> 6993000 | G5: =IF(E5="","",E5/$D$3) -> 59.227727 | H5: =IF(F5="","",F5/$D$3) -> 592.27727 | I5: от 700 000 до 7 млн сум за проект
A6: Сайт | B6: за проект | C6: 10000 | D6: 70000 | E6: =IF(C6="","",C6*$B$3) -> 1398600 | F6: =IF(D6="","",D6*$B$3) -> 9790200 | G6: =IF(E6="","",E6/$D$3) -> 118.45545 | H6: =IF(F6="","",F6/$D$3) -> 829.18818 | I6: от 1,4 до 9,8 млн сум за проект
A7: AI-рилс | B7: за ролик | C7: 500 | D7: 5000 | E7: =IF(C7="","",C7*$B$3) -> 69930 | F7: =IF(D7="","",D7*$B$3) -> 699300 | G7: =IF(E7="","",E7/$D$3) -> 5.9227727 | H7: =IF(F7="","",F7/$D$3) -> 59.227727 | I7: от 70 000 до 700 000 сум за ролик, а одному клиенту их нужно много
A8: Контент-план | B8: за план | C8: 5000 | D8: 20000 | E8: =IF(C8="","",C8*$B$3) -> 699300 | F8: =IF(D8="","",D8*$B$3) -> 2797200 | G8: =IF(E8="","",E8/$D$3) -> 59.227727 | H8: =IF(F8="","",F8/$D$3) -> 236.91091 | I8: от 0,7 до 2,8 млн сум
A9: Ведение соцсетей | B9: в месяц | C9: 20000 | D9: 50000 | E9: =IF(C9="","",C9*$B$3) -> 2797200 | F9: =IF(D9="","",D9*$B$3) -> 6993000 | G9: =IF(E9="","",E9/$D$3) -> 236.91091 | H9: =IF(F9="","",F9/$D$3) -> 592.27727 | I9: от 2,8 до 7 млн сум в месяц
A10: Дизайн | B10: в месяц | C10: 10000 | D10: 40000 | E10: =IF(C10="","",C10*$B$3) -> 1398600 | F10: =IF(D10="","",D10*$B$3) -> 5594400 | G10: =IF(E10="","",E10/$D$3) -> 118.45545 | H10: =IF(F10="","",F10/$D$3) -> 473.82182 | I10: от 1,4 до 5,6 млн сум в месяц
A11: Дизайн: разовые задачи | B11: за задачу | C11: 300 | E11: =IF(C11="","",C11*$B$3) -> 41958 | F11: =IF(D11="","",D11*$B$3) | G11: =IF(E11="","",E11/$D$3) -> 3.5536636 | H11: =IF(F11="","",F11/$D$3) | I11: от 42 000 сум
A13: Сколько заказов окупают тариф (по спеццене, считаем в рублях)
A14: Спеццена тарифа, ₽ (с листа «Цены тарифов») | C14: ='Цены тарифов'!B20 -> 4900 | D14: ='Цены тарифов'!B21 -> 12000 | E14: ='Цены тарифов'!B22 -> 100000
A15: По минимальной цене заказа (осторожный расчёт)
A16: Услуга | B16: Цена одного заказа, ₽ | C16: Окупает «Базовый», заказов | D16: Окупает «Про», заказов | E16: Окупает «Наставничество», заказов
A17: =A5&" ("&B5&")" -> Чат-бот для бизнеса (за проект) | B17: =C5 -> 5000 | C17: =ROUNDUP(C$14/$B17,0) -> 1 | D17: =ROUNDUP(D$14/$B17,0) -> 3 | E17: =ROUNDUP(E$14/$B17,0) -> 20
A18: =A6&" ("&B6&")" -> Сайт (за проект) | B18: =C6 -> 10000 | C18: =ROUNDUP(C$14/$B18,0) -> 1 | D18: =ROUNDUP(D$14/$B18,0) -> 2 | E18: =ROUNDUP(E$14/$B18,0) -> 10
A19: =A7&" ("&B7&")" -> AI-рилс (за ролик) | B19: =C7 -> 500 | C19: =ROUNDUP(C$14/$B19,0) -> 10 | D19: =ROUNDUP(D$14/$B19,0) -> 24 | E19: =ROUNDUP(E$14/$B19,0) -> 200
A20: =A8&" ("&B8&")" -> Контент-план (за план) | B20: =C8 -> 5000 | C20: =ROUNDUP(C$14/$B20,0) -> 1 | D20: =ROUNDUP(D$14/$B20,0) -> 3 | E20: =ROUNDUP(E$14/$B20,0) -> 20
A21: =A9&" ("&B9&")" -> Ведение соцсетей (в месяц) | B21: =C9 -> 20000 | C21: =ROUNDUP(C$14/$B21,0) -> 1 | D21: =ROUNDUP(D$14/$B21,0) -> 1 | E21: =ROUNDUP(E$14/$B21,0) -> 5
A22: =A10&" ("&B10&")" -> Дизайн (в месяц) | B22: =C10 -> 10000 | C22: =ROUNDUP(C$14/$B22,0) -> 1 | D22: =ROUNDUP(D$14/$B22,0) -> 2 | E22: =ROUNDUP(E$14/$B22,0) -> 10
A24: По максимальной цене заказа
A25: Услуга | B25: Цена одного заказа, ₽ | C25: Окупает «Базовый», заказов | D25: Окупает «Про», заказов | E25: Окупает «Наставничество», заказов
A26: =A5&" ("&B5&")" -> Чат-бот для бизнеса (за проект) | B26: =D5 -> 50000 | C26: =ROUNDUP(C$14/$B26,0) -> 1 | D26: =ROUNDUP(D$14/$B26,0) -> 1 | E26: =ROUNDUP(E$14/$B26,0) -> 2
A27: =A6&" ("&B6&")" -> Сайт (за проект) | B27: =D6 -> 70000 | C27: =ROUNDUP(C$14/$B27,0) -> 1 | D27: =ROUNDUP(D$14/$B27,0) -> 1 | E27: =ROUNDUP(E$14/$B27,0) -> 2
A28: =A7&" ("&B7&")" -> AI-рилс (за ролик) | B28: =D7 -> 5000 | C28: =ROUNDUP(C$14/$B28,0) -> 1 | D28: =ROUNDUP(D$14/$B28,0) -> 3 | E28: =ROUNDUP(E$14/$B28,0) -> 20
A29: =A8&" ("&B8&")" -> Контент-план (за план) | B29: =D8 -> 20000 | C29: =ROUNDUP(C$14/$B29,0) -> 1 | D29: =ROUNDUP(D$14/$B29,0) -> 1 | E29: =ROUNDUP(E$14/$B29,0) -> 5
A30: =A9&" ("&B9&")" -> Ведение соцсетей (в месяц) | B30: =D9 -> 50000 | C30: =ROUNDUP(C$14/$B30,0) -> 1 | D30: =ROUNDUP(D$14/$B30,0) -> 1 | E30: =ROUNDUP(E$14/$B30,0) -> 2
A31: =A10&" ("&B10&")" -> Дизайн (в месяц) | B31: =D10 -> 40000 | C31: =ROUNDUP(C$14/$B31,0) -> 1 | D31: =ROUNDUP(D$14/$B31,0) -> 1 | E31: =ROUNDUP(E$14/$B31,0) -> 3
A35: Откуда данные и оговорки
A36: Цены — со слов Васи на созвоне 28.09.2026 («Новая запись 2»). Пересчёт — по курсу ЦБ Узбекистана на 29.09.2026.
A37: По Узбекистану сверены только боты и сайты: бот 0,3–10 млн сум, сайт 3–8 млн сум (research/08-miro-kastdevy-segmenty/research/00-svodka-resercha-i-segmenty.md, отчёт 05, первоисточник не перенесён) — не проверено.
A38: По контенту, рилсам и дизайну данных по Узбекистану в ресёрче проекта нет — не проверено. Пока это цены со слов Васи, не доход учеников.
A39: «Окупает, заказов» — спеццена тарифа ÷ цена одного заказа в рублях, округлено вверх. Не учитывает время и расходы ученика. В «Базовом» нет AI Reels Maker.

Sheet Варианты цен
A1: Варианты ступеней цены: A, B, C
A2: Спеццена везде одна — из созвона. Меняется только наценка для «Зрителей эфира» и «Обычной». Сумы округляются так же, как в презентации.
A4: 1 рубль = сум | B4: ='Цены тарифов'!B7 -> 139.86 | C4: 1 доллар = сум | D4: ='Цены тарифов'!B6 -> 11806.97
A6: Наценки по вариантам
A7: Вариант | B7: «Зрителям эфира» к спеццене | C7: «Обычная» к спеццене | D7: Откуда
A8: A — как в презентации | B8: ='Цены тарифов'!B9 -> 0.25 | C8: ='Цены тарифов'!B10 -> 0.75 | D8: Итог созвона 28.09
A9: B — мягкий шаг | B9: 0.15 | C9: 0.3 | D9: По Дымшакову: меньше похоже на «зачёркнутые» скидки
A10: C — сильный якорь | B10: 0.5 | C10: 1 | D10: По Тимочко: обычная вдвое выше спеццены
A12: Спеццена в рублях и округление (с листа «Цены тарифов»)
A13: Тариф | B13: Спеццена, ₽ | C13: Шаг округления, сум | D13: Хвост, сум
A14: Базовый | B14: ='Цены тарифов'!B20 -> 4900 | C14: ='Цены тарифов'!B14 -> 10000 | D14: ='Цены тарифов'!C14 -> 1000
A15: Про | B15: ='Цены тарифов'!B21 -> 12000 | C15: ='Цены тарифов'!B15 -> 10000 | D15: ='Цены тарифов'!C15 -> 1000
A16: Наставничество | B16: ='Цены тарифов'!B22 -> 100000 | C16: ='Цены тарифов'!B16 -> 100000 | D16: ='Цены тарифов'!C16 -> 10000
A18: Вариант A — как в презентации
A19: Тариф | B19: Спеццена, сум | C19: Зрителям эфира, сум | D19: Обычная, сум | E19: Спеццена, $ | F19: Зрителям эфира, $ | G19: Обычная, $
A20: Базовый | B20: =ROUND(($B14*$B$4+$D14)/$C14,0)*$C14-$D14 -> 689000 | C20: =ROUND(($B14*(1+$B$8)*$B$4+$D14)/$C14,0)*$C14-$D14 -> 859000 | D20: =ROUND(($B14*(1+$C$8)*$B$4+$D14)/$C14,0)*$C14-$D14 -> 1199000 | E20: =ROUND(B20/$D$4,0) -> 58 | F20: =ROUND(C20/$D$4,0) -> 73 | G20: =ROUND(D20/$D$4,0) -> 102
A21: Про | B21: =ROUND(($B15*$B$4+$D15)/$C15,0)*$C15-$D15 -> 1679000 | C21: =ROUND(($B15*(1+$B$8)*$B$4+$D15)/$C15,0)*$C15-$D15 -> 2099000 | D21: =ROUND(($B15*(1+$C$8)*$B$4+$D15)/$C15,0)*$C15-$D15 -> 2939000 | E21: =ROUND(B21/$D$4,0) -> 142 | F21: =ROUND(C21/$D$4,0) -> 178 | G21: =ROUND(D21/$D$4,0) -> 249
A22: Наставничество | B22: =ROUND(($B16*$B$4+$D16)/$C16,0)*$C16-$D16 -> 13990000 | C22: =ROUND(($B16*(1+$B$8)*$B$4+$D16)/$C16,0)*$C16-$D16 -> 17490000 | D22: =ROUND(($B16*(1+$C$8)*$B$4+$D16)/$C16,0)*$C16-$D16 -> 24490000 | E22: =ROUND(B22/$D$4,0) -> 1185 | F22: =ROUND(C22/$D$4,0) -> 1481 | G22: =ROUND(D22/$D$4,0) -> 2074
A24: Вариант B — мягкий шаг
A25: Тариф | B25: Спеццена, сум | C25: Зрителям эфира, сум | D25: Обычная, сум | E25: Спеццена, $ | F25: Зрителям эфира, $ | G25: Обычная, $
A26: Базовый | B26: =ROUND(($B14*$B$4+$D14)/$C14,0)*$C14-$D14 -> 689000 | C26: =ROUND(($B14*(1+$B$9)*$B$4+$D14)/$C14,0)*$C14-$D14 -> 789000 | D26: =ROUND(($B14*(1+$C$9)*$B$4+$D14)/$C14,0)*$C14-$D14 -> 889000 | E26: =ROUND(B26/$D$4,0) -> 58 | F26: =ROUND(C26/$D$4,0) -> 67 | G26: =ROUND(D26/$D$4,0) -> 75
A27: Про | B27: =ROUND(($B15*$B$4+$D15)/$C15,0)*$C15-$D15 -> 1679000 | C27: =ROUND(($B15*(1+$B$9)*$B$4+$D15)/$C15,0)*$C15-$D15 -> 1929000 | D27: =ROUND(($B15*(1+$C$9)*$B$4+$D15)/$C15,0)*$C15-$D15 -> 2179000 | E27: =ROUND(B27/$D$4,0) -> 142 | F27: =ROUND(C27/$D$4,0) -> 163 | G27: =ROUND(D27/$D$4,0) -> 185
A28: Наставничество | B28: =ROUND(($B16*$B$4+$D16)/$C16,0)*$C16-$D16 -> 13990000 | C28: =ROUND(($B16*(1+$B$9)*$B$4+$D16)/$C16,0)*$C16-$D16 -> 16090000 | D28: =ROUND(($B16*(1+$C$9)*$B$4+$D16)/$C16,0)*$C16-$D16 -> 18190000 | E28: =ROUND(B28/$D$4,0) -> 1185 | F28: =ROUND(C28/$D$4,0) -> 1363 | G28: =ROUND(D28/$D$4,0) -> 1541
A30: Вариант C — сильный якорь
A31: Тариф | B31: Спеццена, сум | C31: Зрителям эфира, сум | D31: Обычная, сум | E31: Спеццена, $ | F31: Зрителям эфира, $ | G31: Обычная, $
A32: Базовый | B32: =ROUND(($B14*$B$4+$D14)/$C14,0)*$C14-$D14 -> 689000 | C32: =ROUND(($B14*(1+$B$10)*$B$4+$D14)/$C14,0)*$C14-$D14 -> 1029000 | D32: =ROUND(($B14*(1+$C$10)*$B$4+$D14)/$C14,0)*$C14-$D14 -> 1369000 | E32: =ROUND(B32/$D$4,0) -> 58 | F32: =ROUND(C32/$D$4,0) -> 87 | G32: =ROUND(D32/$D$4,0) -> 116
A33: Про | B33: =ROUND(($B15*$B$4+$D15)/$C15,0)*$C15-$D15 -> 1679000 | C33: =ROUND(($B15*(1+$B$10)*$B$4+$D15)/$C15,0)*$C15-$D15 -> 2519000 | D33: =ROUND(($B15*(1+$C$10)*$B$4+$D15)/$C15,0)*$C15-$D15 -> 3359000 | E33: =ROUND(B33/$D$4,0) -> 142 | F33: =ROUND(C33/$D$4,0) -> 213 | G33: =ROUND(D33/$D$4,0) -> 284
A34: Наставничество | B34: =ROUND(($B16*$B$4+$D16)/$C16,0)*$C16-$D16 -> 13990000 | C34: =ROUND(($B16*(1+$B$10)*$B$4+$D16)/$C16,0)*$C16-$D16 -> 20990000 | D34: =ROUND(($B16*(1+$C$10)*$B$4+$D16)/$C16,0)*$C16-$D16 -> 27990000 | E34: =ROUND(B34/$D$4,0) -> 1185 | F34: =ROUND(C34/$D$4,0) -> 1778 | G34: =ROUND(D34/$D$4,0) -> 2371
A36: Вариант C работает, только если «обычную» цену потом реально брать после запуска, иначе это фиктивная скидка.
